package com.teammetallurgy.atum.worldgen.decorators;

import java.util.Random;

import net.minecraft.block.Block;
import net.minecraft.world.World;
import net.minecraft.world.gen.feature.WorldGenerator;

import com.teammetallurgy.atum.blocks.AtumBlocks;

public class WorldGenPalace extends WorldGenerator {

	public int largeLimestoneBricks;
	public int smallLimestoneBricks;
	public int carvedLimestone;
	public int largeLimestoneBricksStairs;

	public WorldGenPalace() {
		this.largeLimestoneBricks = AtumBlocks.BLOCK_LARGEBRICK.blockID;
		this.smallLimestoneBricks = AtumBlocks.BLOCK_SMALLBRICK.blockID;
		this.carvedLimestone = AtumBlocks.BLOCK_CARVEDBRICK.blockID;
		this.largeLimestoneBricksStairs = AtumBlocks.BLOCK_LARGESTONESTAIRS.blockID;
	}

	@Override
	public boolean generate(World world, Random random, int i, int j, int k) {
		world.setBlock(i + 0, j + 0, k + 8, this.largeLimestoneBricks);
		world.setBlock(i + 0, j + 0, k + 9, this.largeLimestoneBricks);
		world.setBlock(i + 0, j + 0, k + 10, this.largeLimestoneBricks);
		world.setBlock(i + 0, j + 0, k + 11, this.largeLimestoneBricks);
		world.setBlock(i + 0, j + 0, k + 12, this.largeLimestoneBricks);
		world.setBlock(i + 0, j + 0, k + 13, this.largeLimestoneBricks);
		world.setBlock(i + 0, j + 0, k + 14, this.largeLimestoneBricks);
		world.setBlock(i + 0, j + 0, k + 15, this.largeLimestoneBricks);
		world.setBlock(i + 0, j + 0, k + 16, this.largeLimestoneBricks);
		world.setBlock(i + 0, j + 0, k + 17, this.largeLimestoneBricks);
		world.setBlock(i + 0, j + 0, k + 18, this.largeLimestoneBricks);
		world.setBlock(i + 0, j + 0, k + 19, this.largeLimestoneBricks);
		world.setBlock(i + 0, j + 0, k + 20, this.largeLimestoneBricks);
		world.setBlock(i + 0, j + 0, k + 21, this.largeLimestoneBricks);
		world.setBlock(i + 0, j + 0, k + 22, this.largeLimestoneBricks);
		world.setBlock(i + 0, j + 0, k + 23, this.largeLimestoneBricks);
		world.setBlock(i + 0, j + 0, k + 24, this.largeLimestoneBricks);
		world.setBlock(i + 0, j + 0, k + 25, this.largeLimestoneBricks);
		world.setBlock(i + 0, j + 0, k + 26, this.largeLimestoneBricks);
		world.setBlock(i + 0, j + 0, k + 27, this.largeLimestoneBricks);
		world.setBlock(i + 0, j + 0, k + 28, this.largeLimestoneBricks);
		world.setBlock(i + 0, j + 0, k + 29, this.largeLimestoneBricks);
		world.setBlock(i + 0, j + 0, k + 30, this.largeLimestoneBricks);
		world.setBlock(i + 0, j + 0, k + 31, this.largeLimestoneBricks);
		world.setBlock(i + 0, j + 0, k + 32, this.largeLimestoneBricks);
		world.setBlock(i + 0, j + 0, k + 33, this.largeLimestoneBricks);
		world.setBlock(i + 0, j + 0, k + 34, this.largeLimestoneBricks);
		world.setBlock(i + 0, j + 0, k + 35, this.largeLimestoneBricks);
		world.setBlock(i + 0, j + 0, k + 36, this.largeLimestoneBricks);
		world.setBlock(i + 0, j + 0, k + 37, this.largeLimestoneBricks);
		world.setBlock(i + 0, j + 0, k + 38, this.largeLimestoneBricks);
		world.setBlock(i + 0, j + 0, k + 39, this.largeLimestoneBricks);
		world.setBlock(i + 0, j + 0, k + 40, this.largeLimestoneBricks);
		world.setBlock(i + 0, j + 0, k + 41, this.largeLimestoneBricks);
		world.setBlock(i + 0, j + 0, k + 42, this.largeLimestoneBricks);
		world.setBlock(i + 0, j + 0, k + 43, this.largeLimestoneBricks);
		world.setBlock(i + 0, j + 0, k + 44, this.largeLimestoneBricks);
		world.setBlock(i + 0, j + 0, k + 45, this.largeLimestoneBricks);
		world.setBlock(i + 0, j + 0, k + 46, this.largeLimestoneBricks);
		world.setBlock(i + 0, j + 0, k + 47, this.largeLimestoneBricks);
		world.setBlock(i + 0, j + 0, k + 48, this.largeLimestoneBricks);
		world.setBlock(i + 0, j + 0, k + 49, this.largeLimestoneBricks);
		world.setBlock(i + 0, j + 1, k + 8, this.largeLimestoneBricks);
		world.setBlock(i + 0, j + 1, k + 9, this.largeLimestoneBricks);
		world.setBlock(i + 0, j + 1, k + 10, this.largeLimestoneBricks);
		world.setBlock(i + 0, j + 1, k + 11, this.largeLimestoneBricks);
		world.setBlock(i + 0, j + 1, k + 12, this.largeLimestoneBricks);
		world.setBlock(i + 0, j + 1, k + 13, this.largeLimestoneBricks);
		world.setBlock(i + 0, j + 1, k + 14, this.largeLimestoneBricks);
		world.setBlock(i + 0, j + 1, k + 15, this.largeLimestoneBricks);
		world.setBlock(i + 0, j + 1, k + 16, this.largeLimestoneBricks);
		world.setBlock(i + 0, j + 1, k + 17, this.largeLimestoneBricks);
		world.setBlock(i + 0, j + 1, k + 18, this.largeLimestoneBricks);
		world.setBlock(i + 0, j + 1, k + 19, this.largeLimestoneBricks);
		world.setBlock(i + 0, j + 1, k + 20, this.largeLimestoneBricks);
		world.setBlock(i + 0, j + 1, k + 21, this.largeLimestoneBricks);
		world.setBlock(i + 0, j + 1, k + 22, this.largeLimestoneBricks);
		world.setBlock(i + 0, j + 1, k + 23, this.largeLimestoneBricks);
		world.setBlock(i + 0, j + 1, k + 24, this.largeLimestoneBricks);
		world.setBlock(i + 0, j + 1, k + 25, this.largeLimestoneBricks);
		world.setBlock(i + 0, j + 1, k + 26, this.largeLimestoneBricks);
		world.setBlock(i + 0, j + 1, k + 27, this.largeLimestoneBricks);
		world.setBlock(i + 0, j + 1, k + 28, this.largeLimestoneBricks);
		world.setBlock(i + 0, j + 1, k + 29, this.largeLimestoneBricks);
		world.setBlock(i + 0, j + 1, k + 30, this.largeLimestoneBricks);
		world.setBlock(i + 0, j + 1, k + 31, this.largeLimestoneBricks);
		world.setBlock(i + 0, j + 1, k + 32, this.largeLimestoneBricks);
		world.setBlock(i + 0, j + 1, k + 33, this.largeLimestoneBricks);
		world.setBlock(i + 0, j + 1, k + 34, this.largeLimestoneBricks);
		world.setBlock(i + 0, j + 1, k + 35, this.largeLimestoneBricks);
		world.setBlock(i + 0, j + 1, k + 36, this.largeLimestoneBricks);
		world.setBlock(i + 0, j + 1, k + 37, this.largeLimestoneBricks);
		world.setBlock(i + 0, j + 1, k + 38, this.largeLimestoneBricks);
		world.setBlock(i + 0, j + 1, k + 39, this.largeLimestoneBricks);
		world.setBlock(i + 0, j + 1, k + 40, this.largeLimestoneBricks);
		world.setBlock(i + 0, j + 1, k + 41, this.largeLimestoneBricks);
		world.setBlock(i + 0, j + 1, k + 42, this.largeLimestoneBricks);
		world.setBlock(i + 0, j + 1, k + 43, this.largeLimestoneBricks);
		world.setBlock(i + 0, j + 1, k + 44, this.largeLimestoneBricks);
		world.setBlock(i + 0, j + 1, k + 45, this.largeLimestoneBricks);
		world.setBlock(i + 0, j + 1, k + 46, this.largeLimestoneBricks);
		world.setBlock(i + 0, j + 1, k + 47, this.largeLimestoneBricks);
		world.setBlock(i + 0, j + 1, k + 48, this.largeLimestoneBricks);
		world.setBlock(i + 0, j + 1, k + 49, this.largeLimestoneBricks);
		world.setBlock(i + 1, j + 0, k + 8, this.largeLimestoneBricks);
		world.setBlock(i + 1, j + 0, k + 49, this.largeLimestoneBricks);
		world.setBlock(i + 1, j + 1, k + 8, this.largeLimestoneBricks);
		world.setBlock(i + 1, j + 1, k + 9, this.largeLimestoneBricks);
		world.setBlock(i + 1, j + 1, k + 10, this.largeLimestoneBricks);
		world.setBlock(i + 1, j + 1, k + 11, this.largeLimestoneBricks);
		world.setBlock(i + 1, j + 1, k + 12, this.largeLimestoneBricks);
		world.setBlock(i + 1, j + 1, k + 13, this.largeLimestoneBricks);
		world.setBlock(i + 1, j + 1, k + 14, this.largeLimestoneBricks);
		world.setBlock(i + 1, j + 1, k + 15, this.largeLimestoneBricks);
		world.setBlock(i + 1, j + 1, k + 16, this.largeLimestoneBricks);
		world.setBlock(i + 1, j + 1, k + 17, this.largeLimestoneBricks);
		world.setBlock(i + 1, j + 1, k + 18, this.largeLimestoneBricks);
		world.setBlock(i + 1, j + 1, k + 19, this.largeLimestoneBricks);
		world.setBlock(i + 1, j + 1, k + 20, this.largeLimestoneBricks);
		world.setBlock(i + 1, j + 1, k + 21, this.largeLimestoneBricks);
		world.setBlock(i + 1, j + 1, k + 22, this.largeLimestoneBricks);
		world.setBlock(i + 1, j + 1, k + 23, this.largeLimestoneBricks);
		world.setBlock(i + 1, j + 1, k + 24, this.largeLimestoneBricks);
		world.setBlock(i + 1, j + 1, k + 25, this.largeLimestoneBricks);
		world.setBlock(i + 1, j + 1, k + 26, this.largeLimestoneBricks);
		world.setBlock(i + 1, j + 1, k + 27, this.largeLimestoneBricks);
		world.setBlock(i + 1, j + 1, k + 28, this.largeLimestoneBricks);
		world.setBlock(i + 1, j + 1, k + 29, this.largeLimestoneBricks);
		world.setBlock(i + 1, j + 1, k + 30, this.largeLimestoneBricks);
		world.setBlock(i + 1, j + 1, k + 31, this.largeLimestoneBricks);
		world.setBlock(i + 1, j + 1, k + 32, this.largeLimestoneBricks);
		world.setBlock(i + 1, j + 1, k + 33, this.largeLimestoneBricks);
		world.setBlock(i + 1, j + 1, k + 34, this.largeLimestoneBricks);
		world.setBlock(i + 1, j + 1, k + 35, this.largeLimestoneBricks);
		world.setBlock(i + 1, j + 1, k + 36, this.largeLimestoneBricks);
		world.setBlock(i + 1, j + 1, k + 37, this.largeLimestoneBricks);
		world.setBlock(i + 1, j + 1, k + 38, this.largeLimestoneBricks);
		world.setBlock(i + 1, j + 1, k + 39, this.largeLimestoneBricks);
		world.setBlock(i + 1, j + 1, k + 40, this.largeLimestoneBricks);
		world.setBlock(i + 1, j + 1, k + 41, this.largeLimestoneBricks);
		world.setBlock(i + 1, j + 1, k + 42, this.largeLimestoneBricks);
		world.setBlock(i + 1, j + 1, k + 43, this.largeLimestoneBricks);
		world.setBlock(i + 1, j + 1, k + 44, this.largeLimestoneBricks);
		world.setBlock(i + 1, j + 1, k + 45, this.largeLimestoneBricks);
		world.setBlock(i + 1, j + 1, k + 46, this.largeLimestoneBricks);
		world.setBlock(i + 1, j + 1, k + 47, this.largeLimestoneBricks);
		world.setBlock(i + 1, j + 1, k + 48, this.largeLimestoneBricks);
		world.setBlock(i + 1, j + 1, k + 49, this.largeLimestoneBricks);
		world.setBlock(i + 1, j + 2, k + 9, this.largeLimestoneBricks);
		world.setBlock(i + 1, j + 2, k + 12, this.largeLimestoneBricks);
		world.setBlock(i + 1, j + 2, k + 15, this.largeLimestoneBricks);
		world.setBlock(i + 1, j + 2, k + 18, this.largeLimestoneBricks);
		world.setBlock(i + 1, j + 2, k + 21, this.largeLimestoneBricks);
		world.setBlock(i + 1, j + 2, k + 24, this.largeLimestoneBricks);
		world.setBlock(i + 1, j + 2, k + 27, this.largeLimestoneBricks);
		world.setBlock(i + 1, j + 2, k + 30, this.largeLimestoneBricks);
		world.setBlock(i + 1, j + 2, k + 33, this.largeLimestoneBricks);
		world.setBlock(i + 1, j + 2, k + 36, this.largeLimestoneBricks);
		world.setBlock(i + 1, j + 2, k + 39, this.largeLimestoneBricks);
		world.setBlock(i + 1, j + 2, k + 42, this.largeLimestoneBricks);
		world.setBlock(i + 1, j + 2, k + 45, this.largeLimestoneBricks);
		world.setBlock(i + 1, j + 2, k + 48, this.largeLimestoneBricks);
		world.setBlock(i + 1, j + 5, k + 9, this.largeLimestoneBricks);
		world.setBlock(i + 1, j + 5, k + 12, this.largeLimestoneBricks);
		world.setBlock(i + 1, j + 5, k + 15, this.largeLimestoneBricks);
		world.setBlock(i + 1, j + 5, k + 18, this.largeLimestoneBricks);
		world.setBlock(i + 1, j + 5, k + 21, this.largeLimestoneBricks);
		world.setBlock(i + 1, j + 5, k + 24, this.largeLimestoneBricks);
		world.setBlock(i + 1, j + 5, k + 27, this.largeLimestoneBricks);
		world.setBlock(i + 1, j + 5, k + 30, this.largeLimestoneBricks);
		world.setBlock(i + 1, j + 5, k + 33, this.largeLimestoneBricks);
		world.setBlock(i + 1, j + 5, k + 36, this.largeLimestoneBricks);
		world.setBlock(i + 1, j + 5, k + 39, this.largeLimestoneBricks);
		world.setBlock(i + 1, j + 5, k + 42, this.largeLimestoneBricks);
		world.setBlock(i + 1, j + 5, k + 45, this.largeLimestoneBricks);
		world.setBlock(i + 1, j + 5, k + 48, this.largeLimestoneBricks);
		world.setBlock(i + 1, j + 6, k + 9, this.largeLimestoneBricks);
		world.setBlock(i + 1, j + 6, k + 10, this.largeLimestoneBricks);
		world.setBlock(i + 1, j + 6, k + 11, this.largeLimestoneBricks);
		world.setBlock(i + 1, j + 6, k + 12, this.largeLimestoneBricks);
		world.setBlock(i + 1, j + 6, k + 13, this.largeLimestoneBricks);
		world.setBlock(i + 1, j + 6, k + 14, this.largeLimestoneBricks);
		world.setBlock(i + 1, j + 6, k + 15, this.largeLimestoneBricks);
		world.setBlock(i + 1, j + 6, k + 16, this.largeLimestoneBricks);
		world.setBlock(i + 1, j + 6, k + 17, this.largeLimestoneBricks);
		world.setBlock(i + 1, j + 6, k + 18, this.largeLimestoneBricks);
		world.setBlock(i + 1, j + 6, k + 19, this.largeLimestoneBricks);
		world.setBlock(i + 1, j + 6, k + 20, this.largeLimestoneBricks);
		world.setBlock(i + 1, j + 6, k + 21, this.largeLimestoneBricks);
		world.setBlock(i + 1, j + 6, k + 22, this.largeLimestoneBricks);
		world.setBlock(i + 1, j + 6, k + 23, this.largeLimestoneBricks);
		world.setBlock(i + 1, j + 6, k + 24, this.largeLimestoneBricks);
		world.setBlock(i + 1, j + 6, k + 25, this.largeLimestoneBricks);
		world.setBlock(i + 1, j + 6, k + 26, this.largeLimestoneBricks);
		world.setBlock(i + 1, j + 6, k + 27, this.largeLimestoneBricks);
		world.setBlock(i + 1, j + 6, k + 28, this.largeLimestoneBricks);
		world.setBlock(i + 1, j + 6, k + 29, this.largeLimestoneBricks);
		world.setBlock(i + 1, j + 6, k + 30, this.largeLimestoneBricks);
		world.setBlock(i + 1, j + 6, k + 31, this.largeLimestoneBricks);
		world.setBlock(i + 1, j + 6, k + 32, this.largeLimestoneBricks);
		world.setBlock(i + 1, j + 6, k + 33, this.largeLimestoneBricks);
		world.setBlock(i + 1, j + 6, k + 34, this.largeLimestoneBricks);
		world.setBlock(i + 1, j + 6, k + 35, this.largeLimestoneBricks);
		world.setBlock(i + 1, j + 6, k + 36, this.largeLimestoneBricks);
		world.setBlock(i + 1, j + 6, k + 37, this.largeLimestoneBricks);
		world.setBlock(i + 1, j + 6, k + 38, this.largeLimestoneBricks);
		world.setBlock(i + 1, j + 6, k + 39, this.largeLimestoneBricks);
		world.setBlock(i + 1, j + 6, k + 40, this.largeLimestoneBricks);
		world.setBlock(i + 1, j + 6, k + 41, this.largeLimestoneBricks);
		world.setBlock(i + 1, j + 6, k + 42, this.largeLimestoneBricks);
		world.setBlock(i + 1, j + 6, k + 43, this.largeLimestoneBricks);
		world.setBlock(i + 1, j + 6, k + 44, this.largeLimestoneBricks);
		world.setBlock(i + 1, j + 6, k + 45, this.largeLimestoneBricks);
		world.setBlock(i + 1, j + 6, k + 46, this.largeLimestoneBricks);
		world.setBlock(i + 1, j + 6, k + 47, this.largeLimestoneBricks);
		world.setBlock(i + 1, j + 6, k + 48, this.largeLimestoneBricks);
		world.setBlock(i + 2, j + 0, k + 8, this.largeLimestoneBricks);
		world.setBlock(i + 2, j + 0, k + 49, this.largeLimestoneBricks);
		world.setBlock(i + 2, j + 1, k + 8, this.largeLimestoneBricks);
		world.setBlock(i + 2, j + 1, k + 9, this.largeLimestoneBricks);
		world.setBlock(i + 2, j + 1, k + 10, this.largeLimestoneBricks);
		world.setBlock(i + 2, j + 1, k + 11, this.largeLimestoneBricks);
		world.setBlock(i + 2, j + 1, k + 12, this.largeLimestoneBricks);
		world.setBlock(i + 2, j + 1, k + 13, this.largeLimestoneBricks);
		world.setBlock(i + 2, j + 1, k + 14, this.largeLimestoneBricks);
		world.setBlock(i + 2, j + 1, k + 15, this.largeLimestoneBricks);
		world.setBlock(i + 2, j + 1, k + 16, this.largeLimestoneBricks);
		world.setBlock(i + 2, j + 1, k + 17, this.largeLimestoneBricks);
		world.setBlock(i + 2, j + 1, k + 18, this.largeLimestoneBricks);
		world.setBlock(i + 2, j + 1, k + 19, this.largeLimestoneBricks);
		world.setBlock(i + 2, j + 1, k + 20, this.largeLimestoneBricks);
		world.setBlock(i + 2, j + 1, k + 21, this.largeLimestoneBricks);
		world.setBlock(i + 2, j + 1, k + 22, this.largeLimestoneBricks);
		world.setBlock(i + 2, j + 1, k + 23, this.largeLimestoneBricks);
		world.setBlock(i + 2, j + 1, k + 24, this.largeLimestoneBricks);
		world.setBlock(i + 2, j + 1, k + 25, this.largeLimestoneBricks);
		world.setBlock(i + 2, j + 1, k + 26, this.largeLimestoneBricks);
		world.setBlock(i + 2, j + 1, k + 27, this.largeLimestoneBricks);
		world.setBlock(i + 2, j + 1, k + 28, this.largeLimestoneBricks);
		world.setBlock(i + 2, j + 1, k + 29, this.largeLimestoneBricks);
		world.setBlock(i + 2, j + 1, k + 30, this.largeLimestoneBricks);
		world.setBlock(i + 2, j + 1, k + 31, this.largeLimestoneBricks);
		world.setBlock(i + 2, j + 1, k + 32, this.largeLimestoneBricks);
		world.setBlock(i + 2, j + 1, k + 33, this.largeLimestoneBricks);
		world.setBlock(i + 2, j + 1, k + 34, this.largeLimestoneBricks);
		world.setBlock(i + 2, j + 1, k + 35, this.largeLimestoneBricks);
		world.setBlock(i + 2, j + 1, k + 36, this.largeLimestoneBricks);
		world.setBlock(i + 2, j + 1, k + 37, this.largeLimestoneBricks);
		world.setBlock(i + 2, j + 1, k + 38, this.largeLimestoneBricks);
		world.setBlock(i + 2, j + 1, k + 39, this.largeLimestoneBricks);
		world.setBlock(i + 2, j + 1, k + 40, this.largeLimestoneBricks);
		world.setBlock(i + 2, j + 1, k + 41, this.largeLimestoneBricks);
		world.setBlock(i + 2, j + 1, k + 42, this.largeLimestoneBricks);
		world.setBlock(i + 2, j + 1, k + 43, this.largeLimestoneBricks);
		world.setBlock(i + 2, j + 1, k + 44, this.largeLimestoneBricks);
		world.setBlock(i + 2, j + 1, k + 45, this.largeLimestoneBricks);
		world.setBlock(i + 2, j + 1, k + 46, this.largeLimestoneBricks);
		world.setBlock(i + 2, j + 1, k + 47, this.largeLimestoneBricks);
		world.setBlock(i + 2, j + 1, k + 48, this.largeLimestoneBricks);
		world.setBlock(i + 2, j + 1, k + 49, this.largeLimestoneBricks);
		world.setBlock(i + 2, j + 6, k + 9, this.largeLimestoneBricks);
		world.setBlock(i + 2, j + 6, k + 10, this.largeLimestoneBricks);
		world.setBlock(i + 2, j + 6, k + 11, this.largeLimestoneBricks);
		world.setBlock(i + 2, j + 6, k + 12, this.largeLimestoneBricks);
		world.setBlock(i + 2, j + 6, k + 13, this.largeLimestoneBricks);
		world.setBlock(i + 2, j + 6, k + 14, this.largeLimestoneBricks);
		world.setBlock(i + 2, j + 6, k + 15, this.largeLimestoneBricks);
		world.setBlock(i + 2, j + 6, k + 16, this.largeLimestoneBricks);
		world.setBlock(i + 2, j + 6, k + 17, this.largeLimestoneBricks);
		world.setBlock(i + 2, j + 6, k + 18, this.largeLimestoneBricks);
		world.setBlock(i + 2, j + 6, k + 19, this.largeLimestoneBricks);
		world.setBlock(i + 2, j + 6, k + 20, this.largeLimestoneBricks);
		world.setBlock(i + 2, j + 6, k + 21, this.largeLimestoneBricks);
		world.setBlock(i + 2, j + 6, k + 22, this.largeLimestoneBricks);
		world.setBlock(i + 2, j + 6, k + 23, this.largeLimestoneBricks);
		world.setBlock(i + 2, j + 6, k + 24, this.largeLimestoneBricks);
		world.setBlock(i + 2, j + 6, k + 25, this.largeLimestoneBricks);
		world.setBlock(i + 2, j + 6, k + 26, this.largeLimestoneBricks);
		world.setBlock(i + 2, j + 6, k + 27, this.largeLimestoneBricks);
		world.setBlock(i + 2, j + 6, k + 28, this.largeLimestoneBricks);
		world.setBlock(i + 2, j + 6, k + 29, this.largeLimestoneBricks);
		world.setBlock(i + 2, j + 6, k + 30, this.largeLimestoneBricks);
		world.setBlock(i + 2, j + 6, k + 31, this.largeLimestoneBricks);
		world.setBlock(i + 2, j + 6, k + 32, this.largeLimestoneBricks);
		world.setBlock(i + 2, j + 6, k + 33, this.largeLimestoneBricks);
		world.setBlock(i + 2, j + 6, k + 34, this.largeLimestoneBricks);
		world.setBlock(i + 2, j + 6, k + 35, this.largeLimestoneBricks);
		world.setBlock(i + 2, j + 6, k + 36, this.largeLimestoneBricks);
		world.setBlock(i + 2, j + 6, k + 37, this.largeLimestoneBricks);
		world.setBlock(i + 2, j + 6, k + 38, this.largeLimestoneBricks);
		world.setBlock(i + 2, j + 6, k + 39, this.largeLimestoneBricks);
		world.setBlock(i + 2, j + 6, k + 40, this.largeLimestoneBricks);
		world.setBlock(i + 2, j + 6, k + 41, this.largeLimestoneBricks);
		world.setBlock(i + 2, j + 6, k + 42, this.largeLimestoneBricks);
		world.setBlock(i + 2, j + 6, k + 43, this.largeLimestoneBricks);
		world.setBlock(i + 2, j + 6, k + 44, this.largeLimestoneBricks);
		world.setBlock(i + 2, j + 6, k + 45, this.largeLimestoneBricks);
		world.setBlock(i + 2, j + 6, k + 46, this.largeLimestoneBricks);
		world.setBlock(i + 2, j + 6, k + 47, this.largeLimestoneBricks);
		world.setBlock(i + 2, j + 6, k + 48, this.largeLimestoneBricks);
		world.setBlock(i + 3, j + 0, k + 8, this.largeLimestoneBricks);
		world.setBlock(i + 3, j + 0, k + 49, this.largeLimestoneBricks);
		world.setBlock(i + 3, j + 1, k + 8, this.largeLimestoneBricks);
		world.setBlock(i + 3, j + 1, k + 9, this.largeLimestoneBricks);
		world.setBlock(i + 3, j + 1, k + 10, this.largeLimestoneBricks);
		world.setBlock(i + 3, j + 1, k + 11, this.largeLimestoneBricks);
		world.setBlock(i + 3, j + 1, k + 12, this.largeLimestoneBricks);
		world.setBlock(i + 3, j + 1, k + 13, this.largeLimestoneBricks);
		world.setBlock(i + 3, j + 1, k + 14, this.largeLimestoneBricks);
		world.setBlock(i + 3, j + 1, k + 15, this.largeLimestoneBricks);
		world.setBlock(i + 3, j + 1, k + 16, this.largeLimestoneBricks);
		world.setBlock(i + 3, j + 1, k + 17, this.largeLimestoneBricks);
		world.setBlock(i + 3, j + 1, k + 18, this.largeLimestoneBricks);
		world.setBlock(i + 3, j + 1, k + 19, this.largeLimestoneBricks);
		world.setBlock(i + 3, j + 1, k + 20, this.largeLimestoneBricks);
		world.setBlock(i + 3, j + 1, k + 21, this.largeLimestoneBricks);
		world.setBlock(i + 3, j + 1, k + 22, this.largeLimestoneBricks);
		world.setBlock(i + 3, j + 1, k + 23, this.largeLimestoneBricks);
		world.setBlock(i + 3, j + 1, k + 24, this.largeLimestoneBricks);
		world.setBlock(i + 3, j + 1, k + 25, this.largeLimestoneBricks);
		world.setBlock(i + 3, j + 1, k + 26, this.largeLimestoneBricks);
		world.setBlock(i + 3, j + 1, k + 27, this.largeLimestoneBricks);
		world.setBlock(i + 3, j + 1, k + 28, this.largeLimestoneBricks);
		world.setBlock(i + 3, j + 1, k + 29, this.largeLimestoneBricks);
		world.setBlock(i + 3, j + 1, k + 30, this.largeLimestoneBricks);
		world.setBlock(i + 3, j + 1, k + 31, this.largeLimestoneBricks);
		world.setBlock(i + 3, j + 1, k + 32, this.largeLimestoneBricks);
		world.setBlock(i + 3, j + 1, k + 33, this.largeLimestoneBricks);
		world.setBlock(i + 3, j + 1, k + 34, this.largeLimestoneBricks);
		world.setBlock(i + 3, j + 1, k + 35, this.largeLimestoneBricks);
		world.setBlock(i + 3, j + 1, k + 36, this.largeLimestoneBricks);
		world.setBlock(i + 3, j + 1, k + 37, this.largeLimestoneBricks);
		world.setBlock(i + 3, j + 1, k + 38, this.largeLimestoneBricks);
		world.setBlock(i + 3, j + 1, k + 39, this.largeLimestoneBricks);
		world.setBlock(i + 3, j + 1, k + 40, this.largeLimestoneBricks);
		world.setBlock(i + 3, j + 1, k + 41, this.largeLimestoneBricks);
		world.setBlock(i + 3, j + 1, k + 42, this.largeLimestoneBricks);
		world.setBlock(i + 3, j + 1, k + 43, this.largeLimestoneBricks);
		world.setBlock(i + 3, j + 1, k + 44, this.largeLimestoneBricks);
		world.setBlock(i + 3, j + 1, k + 45, this.largeLimestoneBricks);
		world.setBlock(i + 3, j + 1, k + 46, this.largeLimestoneBricks);
		world.setBlock(i + 3, j + 1, k + 47, this.largeLimestoneBricks);
		world.setBlock(i + 3, j + 1, k + 48, this.largeLimestoneBricks);
		world.setBlock(i + 3, j + 1, k + 49, this.largeLimestoneBricks);
		world.setBlock(i + 3, j + 6, k + 9, this.largeLimestoneBricks);
		world.setBlock(i + 3, j + 6, k + 10, this.largeLimestoneBricks);
		world.setBlock(i + 3, j + 6, k + 11, this.largeLimestoneBricks);
		world.setBlock(i + 3, j + 6, k + 12, this.largeLimestoneBricks);
		world.setBlock(i + 3, j + 6, k + 13, this.largeLimestoneBricks);
		world.setBlock(i + 3, j + 6, k + 14, this.largeLimestoneBricks);
		world.setBlock(i + 3, j + 6, k + 15, this.largeLimestoneBricks);
		world.setBlock(i + 3, j + 6, k + 16, this.largeLimestoneBricks);
		world.setBlock(i + 3, j + 6, k + 17, this.largeLimestoneBricks);
		world.setBlock(i + 3, j + 6, k + 18, this.largeLimestoneBricks);
		world.setBlock(i + 3, j + 6, k + 19, this.largeLimestoneBricks);
		world.setBlock(i + 3, j + 6, k + 20, this.largeLimestoneBricks);
		world.setBlock(i + 3, j + 6, k + 21, this.largeLimestoneBricks);
		world.setBlock(i + 3, j + 6, k + 22, this.largeLimestoneBricks);
		world.setBlock(i + 3, j + 6, k + 23, this.largeLimestoneBricks);
		world.setBlock(i + 3, j + 6, k + 24, this.largeLimestoneBricks);
		world.setBlock(i + 3, j + 6, k + 25, this.largeLimestoneBricks);
		world.setBlock(i + 3, j + 6, k + 26, this.largeLimestoneBricks);
		world.setBlock(i + 3, j + 6, k + 27, this.largeLimestoneBricks);
		world.setBlock(i + 3, j + 6, k + 28, this.largeLimestoneBricks);
		world.setBlock(i + 3, j + 6, k + 29, this.largeLimestoneBricks);
		world.setBlock(i + 3, j + 6, k + 30, this.largeLimestoneBricks);
		world.setBlock(i + 3, j + 6, k + 31, this.largeLimestoneBricks);
		world.setBlock(i + 3, j + 6, k + 32, this.largeLimestoneBricks);
		world.setBlock(i + 3, j + 6, k + 33, this.largeLimestoneBricks);
		world.setBlock(i + 3, j + 6, k + 34, this.largeLimestoneBricks);
		world.setBlock(i + 3, j + 6, k + 35, this.largeLimestoneBricks);
		world.setBlock(i + 3, j + 6, k + 36, this.largeLimestoneBricks);
		world.setBlock(i + 3, j + 6, k + 37, this.largeLimestoneBricks);
		world.setBlock(i + 3, j + 6, k + 38, this.largeLimestoneBricks);
		world.setBlock(i + 3, j + 6, k + 39, this.largeLimestoneBricks);
		world.setBlock(i + 3, j + 6, k + 40, this.largeLimestoneBricks);
		world.setBlock(i + 3, j + 6, k + 41, this.largeLimestoneBricks);
		world.setBlock(i + 3, j + 6, k + 42, this.largeLimestoneBricks);
		world.setBlock(i + 3, j + 6, k + 43, this.largeLimestoneBricks);
		world.setBlock(i + 3, j + 6, k + 44, this.largeLimestoneBricks);
		world.setBlock(i + 3, j + 6, k + 45, this.largeLimestoneBricks);
		world.setBlock(i + 3, j + 6, k + 46, this.largeLimestoneBricks);
		world.setBlock(i + 3, j + 6, k + 47, this.largeLimestoneBricks);
		world.setBlock(i + 3, j + 6, k + 48, this.largeLimestoneBricks);
		world.setBlock(i + 4, j + 0, k + 8, this.largeLimestoneBricks);
		world.setBlock(i + 4, j + 0, k + 49, this.largeLimestoneBricks);
		world.setBlock(i + 4, j + 1, k + 8, this.largeLimestoneBricks);
		world.setBlock(i + 4, j + 1, k + 9, this.largeLimestoneBricks);
		world.setBlock(i + 4, j + 1, k + 10, this.largeLimestoneBricks);
		world.setBlock(i + 4, j + 1, k + 11, this.largeLimestoneBricks);
		world.setBlock(i + 4, j + 1, k + 12, this.largeLimestoneBricks);
		world.setBlock(i + 4, j + 1, k + 13, this.largeLimestoneBricks);
		world.setBlock(i + 4, j + 1, k + 14, this.largeLimestoneBricks);
		world.setBlock(i + 4, j + 1, k + 15, this.largeLimestoneBricks);
		world.setBlock(i + 4, j + 1, k + 16, this.largeLimestoneBricks);
		world.setBlock(i + 4, j + 1, k + 17, this.largeLimestoneBricks);
		world.setBlock(i + 4, j + 1, k + 18, this.largeLimestoneBricks);
		world.setBlock(i + 4, j + 1, k + 19, this.largeLimestoneBricks);
		world.setBlock(i + 4, j + 1, k + 20, this.largeLimestoneBricks);
		world.setBlock(i + 4, j + 1, k + 21, this.largeLimestoneBricks);
		world.setBlock(i + 4, j + 1, k + 22, this.largeLimestoneBricks);
		world.setBlock(i + 4, j + 1, k + 23, this.largeLimestoneBricks);
		world.setBlock(i + 4, j + 1, k + 24, this.largeLimestoneBricks);
		world.setBlock(i + 4, j + 1, k + 25, this.largeLimestoneBricks);
		world.setBlock(i + 4, j + 1, k + 26, this.largeLimestoneBricks);
		world.setBlock(i + 4, j + 1, k + 27, this.largeLimestoneBricks);
		world.setBlock(i + 4, j + 1, k + 28, this.largeLimestoneBricks);
		world.setBlock(i + 4, j + 1, k + 29, this.largeLimestoneBricks);
		world.setBlock(i + 4, j + 1, k + 30, this.largeLimestoneBricks);
		world.setBlock(i + 4, j + 1, k + 31, this.largeLimestoneBricks);
		world.setBlock(i + 4, j + 1, k + 32, this.largeLimestoneBricks);
		world.setBlock(i + 4, j + 1, k + 33, this.largeLimestoneBricks);
		world.setBlock(i + 4, j + 1, k + 34, this.largeLimestoneBricks);
		world.setBlock(i + 4, j + 1, k + 35, this.largeLimestoneBricks);
		world.setBlock(i + 4, j + 1, k + 36, this.largeLimestoneBricks);
		world.setBlock(i + 4, j + 1, k + 37, this.largeLimestoneBricks);
		world.setBlock(i + 4, j + 1, k + 38, this.largeLimestoneBricks);
		world.setBlock(i + 4, j + 1, k + 39, this.largeLimestoneBricks);
		world.setBlock(i + 4, j + 1, k + 40, this.largeLimestoneBricks);
		world.setBlock(i + 4, j + 1, k + 41, this.largeLimestoneBricks);
		world.setBlock(i + 4, j + 1, k + 42, this.largeLimestoneBricks);
		world.setBlock(i + 4, j + 1, k + 43, this.largeLimestoneBricks);
		world.setBlock(i + 4, j + 1, k + 44, this.largeLimestoneBricks);
		world.setBlock(i + 4, j + 1, k + 45, this.largeLimestoneBricks);
		world.setBlock(i + 4, j + 1, k + 46, this.largeLimestoneBricks);
		world.setBlock(i + 4, j + 1, k + 47, this.largeLimestoneBricks);
		world.setBlock(i + 4, j + 1, k + 48, this.largeLimestoneBricks);
		world.setBlock(i + 4, j + 1, k + 49, this.largeLimestoneBricks);
		world.setBlock(i + 4, j + 2, k + 9, this.largeLimestoneBricks);
		world.setBlock(i + 4, j + 2, k + 48, this.largeLimestoneBricks);
		world.setBlock(i + 4, j + 5, k + 9, this.largeLimestoneBricks);
		world.setBlock(i + 4, j + 5, k + 48, this.largeLimestoneBricks);
		world.setBlock(i + 4, j + 6, k + 9, this.largeLimestoneBricks);
		world.setBlock(i + 4, j + 6, k + 10, this.largeLimestoneBricks);
		world.setBlock(i + 4, j + 6, k + 11, this.largeLimestoneBricks);
		world.setBlock(i + 4, j + 6, k + 12, this.largeLimestoneBricks);
		world.setBlock(i + 4, j + 6, k + 13, this.largeLimestoneBricks);
		world.setBlock(i + 4, j + 6, k + 14, this.largeLimestoneBricks);
		world.setBlock(i + 4, j + 6, k + 15, this.largeLimestoneBricks);
		world.setBlock(i + 4, j + 6, k + 16, this.largeLimestoneBricks);
		world.setBlock(i + 4, j + 6, k + 17, this.largeLimestoneBricks);
		world.setBlock(i + 4, j + 6, k + 18, this.largeLimestoneBricks);
		world.setBlock(i + 4, j + 6, k + 19, this.largeLimestoneBricks);
		world.setBlock(i + 4, j + 6, k + 20, this.largeLimestoneBricks);
		world.setBlock(i + 4, j + 6, k + 21, this.largeLimestoneBricks);
		world.setBlock(i + 4, j + 6, k + 22, this.largeLimestoneBricks);
		world.setBlock(i + 4, j + 6, k + 23, this.largeLimestoneBricks);
		world.setBlock(i + 4, j + 6, k + 24, this.largeLimestoneBricks);
		world.setBlock(i + 4, j + 6, k + 25, this.largeLimestoneBricks);
		world.setBlock(i + 4, j + 6, k + 26, this.largeLimestoneBricks);
		world.setBlock(i + 4, j + 6, k + 27, this.largeLimestoneBricks);
		world.setBlock(i + 4, j + 6, k + 28, this.largeLimestoneBricks);
		world.setBlock(i + 4, j + 6, k + 29, this.largeLimestoneBricks);
		world.setBlock(i + 4, j + 6, k + 30, this.largeLimestoneBricks);
		world.setBlock(i + 4, j + 6, k + 31, this.largeLimestoneBricks);
		world.setBlock(i + 4, j + 6, k + 32, this.largeLimestoneBricks);
		world.setBlock(i + 4, j + 6, k + 33, this.largeLimestoneBricks);
		world.setBlock(i + 4, j + 6, k + 34, this.largeLimestoneBricks);
		world.setBlock(i + 4, j + 6, k + 35, this.largeLimestoneBricks);
		world.setBlock(i + 4, j + 6, k + 36, this.largeLimestoneBricks);
		world.setBlock(i + 4, j + 6, k + 37, this.largeLimestoneBricks);
		world.setBlock(i + 4, j + 6, k + 38, this.largeLimestoneBricks);
		world.setBlock(i + 4, j + 6, k + 39, this.largeLimestoneBricks);
		world.setBlock(i + 4, j + 6, k + 40, this.largeLimestoneBricks);
		world.setBlock(i + 4, j + 6, k + 41, this.largeLimestoneBricks);
		world.setBlock(i + 4, j + 6, k + 42, this.largeLimestoneBricks);
		world.setBlock(i + 4, j + 6, k + 43, this.largeLimestoneBricks);
		world.setBlock(i + 4, j + 6, k + 44, this.largeLimestoneBricks);
		world.setBlock(i + 4, j + 6, k + 45, this.largeLimestoneBricks);
		world.setBlock(i + 4, j + 6, k + 46, this.largeLimestoneBricks);
		world.setBlock(i + 4, j + 6, k + 47, this.largeLimestoneBricks);
		world.setBlock(i + 4, j + 6, k + 48, this.largeLimestoneBricks);
		world.setBlock(i + 5, j + 0, k + 8, this.largeLimestoneBricks);
		world.setBlock(i + 5, j + 0, k + 49, this.largeLimestoneBricks);
		world.setBlock(i + 5, j + 1, k + 8, this.largeLimestoneBricks);
		world.setBlock(i + 5, j + 1, k + 9, this.largeLimestoneBricks);
		world.setBlock(i + 5, j + 1, k + 10, this.largeLimestoneBricks);
		world.setBlock(i + 5, j + 1, k + 11, this.largeLimestoneBricks);
		world.setBlock(i + 5, j + 1, k + 12, this.largeLimestoneBricks);
		world.setBlock(i + 5, j + 1, k + 13, this.largeLimestoneBricks);
		world.setBlock(i + 5, j + 1, k + 14, this.largeLimestoneBricks);
		world.setBlock(i + 5, j + 1, k + 15, this.largeLimestoneBricks);
		world.setBlock(i + 5, j + 1, k + 16, this.largeLimestoneBricks);
		world.setBlock(i + 5, j + 1, k + 17, this.largeLimestoneBricks);
		world.setBlock(i + 5, j + 1, k + 18, this.largeLimestoneBricks);
		world.setBlock(i + 5, j + 1, k + 19, this.largeLimestoneBricks);
		world.setBlock(i + 5, j + 1, k + 20, this.largeLimestoneBricks);
		world.setBlock(i + 5, j + 1, k + 21, this.largeLimestoneBricks);
		world.setBlock(i + 5, j + 1, k + 22, this.largeLimestoneBricks);
		world.setBlock(i + 5, j + 1, k + 23, this.largeLimestoneBricks);
		world.setBlock(i + 5, j + 1, k + 24, this.largeLimestoneBricks);
		world.setBlock(i + 5, j + 1, k + 25, this.largeLimestoneBricks);
		world.setBlock(i + 5, j + 1, k + 26, this.largeLimestoneBricks);
		world.setBlock(i + 5, j + 1, k + 27, this.largeLimestoneBricks);
		world.setBlock(i + 5, j + 1, k + 28, this.largeLimestoneBricks);
		world.setBlock(i + 5, j + 1, k + 29, this.largeLimestoneBricks);
		world.setBlock(i + 5, j + 1, k + 30, this.largeLimestoneBricks);
		world.setBlock(i + 5, j + 1, k + 31, this.largeLimestoneBricks);
		world.setBlock(i + 5, j + 1, k + 32, this.largeLimestoneBricks);
		world.setBlock(i + 5, j + 1, k + 33, this.largeLimestoneBricks);
		world.setBlock(i + 5, j + 1, k + 34, this.largeLimestoneBricks);
		world.setBlock(i + 5, j + 1, k + 35, this.largeLimestoneBricks);
		world.setBlock(i + 5, j + 1, k + 36, this.largeLimestoneBricks);
		world.setBlock(i + 5, j + 1, k + 37, this.largeLimestoneBricks);
		world.setBlock(i + 5, j + 1, k + 38, this.largeLimestoneBricks);
		world.setBlock(i + 5, j + 1, k + 39, this.largeLimestoneBricks);
		world.setBlock(i + 5, j + 1, k + 40, this.largeLimestoneBricks);
		world.setBlock(i + 5, j + 1, k + 41, this.largeLimestoneBricks);
		world.setBlock(i + 5, j + 1, k + 42, this.largeLimestoneBricks);
		world.setBlock(i + 5, j + 1, k + 43, this.largeLimestoneBricks);
		world.setBlock(i + 5, j + 1, k + 44, this.largeLimestoneBricks);
		world.setBlock(i + 5, j + 1, k + 45, this.largeLimestoneBricks);
		world.setBlock(i + 5, j + 1, k + 46, this.largeLimestoneBricks);
		world.setBlock(i + 5, j + 1, k + 47, this.largeLimestoneBricks);
		world.setBlock(i + 5, j + 1, k + 48, this.largeLimestoneBricks);
		world.setBlock(i + 5, j + 1, k + 49, this.largeLimestoneBricks);
		world.setBlock(i + 5, j + 6, k + 9, this.largeLimestoneBricks);
		world.setBlock(i + 5, j + 6, k + 10, this.largeLimestoneBricks);
		world.setBlock(i + 5, j + 6, k + 11, this.largeLimestoneBricks);
		world.setBlock(i + 5, j + 6, k + 12, this.largeLimestoneBricks);
		world.setBlock(i + 5, j + 6, k + 13, this.largeLimestoneBricks);
		world.setBlock(i + 5, j + 6, k + 14, this.largeLimestoneBricks);
		world.setBlock(i + 5, j + 6, k + 15, this.largeLimestoneBricks);
		world.setBlock(i + 5, j + 6, k + 16, this.largeLimestoneBricks);
		world.setBlock(i + 5, j + 6, k + 17, this.largeLimestoneBricks);
		world.setBlock(i + 5, j + 6, k + 18, this.largeLimestoneBricks);
		world.setBlock(i + 5, j + 6, k + 19, this.largeLimestoneBricks);
		world.setBlock(i + 5, j + 6, k + 20, this.largeLimestoneBricks);
		world.setBlock(i + 5, j + 6, k + 21, this.largeLimestoneBricks);
		world.setBlock(i + 5, j + 6, k + 22, this.largeLimestoneBricks);
		world.setBlock(i + 5, j + 6, k + 23, this.largeLimestoneBricks);
		world.setBlock(i + 5, j + 6, k + 24, this.largeLimestoneBricks);
		world.setBlock(i + 5, j + 6, k + 25, this.largeLimestoneBricks);
		world.setBlock(i + 5, j + 6, k + 26, this.largeLimestoneBricks);
		world.setBlock(i + 5, j + 6, k + 27, this.largeLimestoneBricks);
		world.setBlock(i + 5, j + 6, k + 28, this.largeLimestoneBricks);
		world.setBlock(i + 5, j + 6, k + 29, this.largeLimestoneBricks);
		world.setBlock(i + 5, j + 6, k + 30, this.largeLimestoneBricks);
		world.setBlock(i + 5, j + 6, k + 31, this.largeLimestoneBricks);
		world.setBlock(i + 5, j + 6, k + 32, this.largeLimestoneBricks);
		world.setBlock(i + 5, j + 6, k + 33, this.largeLimestoneBricks);
		world.setBlock(i + 5, j + 6, k + 34, this.largeLimestoneBricks);
		world.setBlock(i + 5, j + 6, k + 35, this.largeLimestoneBricks);
		world.setBlock(i + 5, j + 6, k + 36, this.largeLimestoneBricks);
		world.setBlock(i + 5, j + 6, k + 37, this.largeLimestoneBricks);
		world.setBlock(i + 5, j + 6, k + 38, this.largeLimestoneBricks);
		world.setBlock(i + 5, j + 6, k + 39, this.largeLimestoneBricks);
		world.setBlock(i + 5, j + 6, k + 40, this.largeLimestoneBricks);
		world.setBlock(i + 5, j + 6, k + 41, this.largeLimestoneBricks);
		world.setBlock(i + 5, j + 6, k + 42, this.largeLimestoneBricks);
		world.setBlock(i + 5, j + 6, k + 43, this.largeLimestoneBricks);
		world.setBlock(i + 5, j + 6, k + 44, this.largeLimestoneBricks);
		world.setBlock(i + 5, j + 6, k + 45, this.largeLimestoneBricks);
		world.setBlock(i + 5, j + 6, k + 46, this.largeLimestoneBricks);
		world.setBlock(i + 5, j + 6, k + 47, this.largeLimestoneBricks);
		world.setBlock(i + 5, j + 6, k + 48, this.largeLimestoneBricks);
		world.setBlock(i + 6, j + 0, k + 8, this.largeLimestoneBricks);
		world.setBlock(i + 6, j + 0, k + 49, this.largeLimestoneBricks);
		world.setBlock(i + 6, j + 1, k + 8, this.largeLimestoneBricks);
		world.setBlock(i + 6, j + 1, k + 9, this.largeLimestoneBricks);
		world.setBlock(i + 6, j + 1, k + 10, this.largeLimestoneBricks);
		world.setBlock(i + 6, j + 1, k + 11, this.largeLimestoneBricks);
		world.setBlock(i + 6, j + 1, k + 12, this.largeLimestoneBricks);
		world.setBlock(i + 6, j + 1, k + 13, this.largeLimestoneBricks);
		world.setBlock(i + 6, j + 1, k + 14, this.largeLimestoneBricks);
		world.setBlock(i + 6, j + 1, k + 15, this.largeLimestoneBricks);
		world.setBlock(i + 6, j + 1, k + 16, this.largeLimestoneBricks);
		world.setBlock(i + 6, j + 1, k + 17, this.largeLimestoneBricks);
		world.setBlock(i + 6, j + 1, k + 18, this.largeLimestoneBricks);
		world.setBlock(i + 6, j + 1, k + 19, this.largeLimestoneBricks);
		world.setBlock(i + 6, j + 1, k + 20, this.largeLimestoneBricks);
		world.setBlock(i + 6, j + 1, k + 21, this.largeLimestoneBricks);
		world.setBlock(i + 6, j + 1, k + 22, this.largeLimestoneBricks);
		world.setBlock(i + 6, j + 1, k + 23, this.largeLimestoneBricks);
		world.setBlock(i + 6, j + 1, k + 24, this.largeLimestoneBricks);
		world.setBlock(i + 6, j + 1, k + 25, this.largeLimestoneBricks);
		world.setBlock(i + 6, j + 1, k + 26, this.largeLimestoneBricks);
		world.setBlock(i + 6, j + 1, k + 27, this.largeLimestoneBricks);
		world.setBlock(i + 6, j + 1, k + 28, this.largeLimestoneBricks);
		world.setBlock(i + 6, j + 1, k + 29, this.largeLimestoneBricks);
		world.setBlock(i + 6, j + 1, k + 30, this.largeLimestoneBricks);
		world.setBlock(i + 6, j + 1, k + 31, this.largeLimestoneBricks);
		world.setBlock(i + 6, j + 1, k + 32, this.largeLimestoneBricks);
		world.setBlock(i + 6, j + 1, k + 33, this.largeLimestoneBricks);
		world.setBlock(i + 6, j + 1, k + 34, this.largeLimestoneBricks);
		world.setBlock(i + 6, j + 1, k + 35, this.largeLimestoneBricks);
		world.setBlock(i + 6, j + 1, k + 36, this.largeLimestoneBricks);
		world.setBlock(i + 6, j + 1, k + 37, this.largeLimestoneBricks);
		world.setBlock(i + 6, j + 1, k + 38, this.largeLimestoneBricks);
		world.setBlock(i + 6, j + 1, k + 39, this.largeLimestoneBricks);
		world.setBlock(i + 6, j + 1, k + 40, this.largeLimestoneBricks);
		world.setBlock(i + 6, j + 1, k + 41, this.largeLimestoneBricks);
		world.setBlock(i + 6, j + 1, k + 42, this.largeLimestoneBricks);
		world.setBlock(i + 6, j + 1, k + 43, this.largeLimestoneBricks);
		world.setBlock(i + 6, j + 1, k + 44, this.largeLimestoneBricks);
		world.setBlock(i + 6, j + 1, k + 45, this.largeLimestoneBricks);
		world.setBlock(i + 6, j + 1, k + 46, this.largeLimestoneBricks);
		world.setBlock(i + 6, j + 1, k + 47, this.largeLimestoneBricks);
		world.setBlock(i + 6, j + 1, k + 48, this.largeLimestoneBricks);
		world.setBlock(i + 6, j + 1, k + 49, this.largeLimestoneBricks);
		world.setBlock(i + 6, j + 2, k + 15, this.largeLimestoneBricks);
		world.setBlock(i + 6, j + 2, k + 18, this.largeLimestoneBricks);
		world.setBlock(i + 6, j + 2, k + 21, this.largeLimestoneBricks);
		world.setBlock(i + 6, j + 2, k + 24, this.largeLimestoneBricks);
		world.setBlock(i + 6, j + 2, k + 27, this.largeLimestoneBricks);
		world.setBlock(i + 6, j + 2, k + 30, this.largeLimestoneBricks);
		world.setBlock(i + 6, j + 2, k + 33, this.largeLimestoneBricks);
		world.setBlock(i + 6, j + 2, k + 36, this.largeLimestoneBricks);
		world.setBlock(i + 6, j + 2, k + 39, this.largeLimestoneBricks);
		world.setBlock(i + 6, j + 2, k + 42, this.largeLimestoneBricks);
		world.setBlock(i + 6, j + 5, k + 15, this.largeLimestoneBricks);
		world.setBlock(i + 6, j + 5, k + 18, this.largeLimestoneBricks);
		world.setBlock(i + 6, j + 5, k + 21, this.largeLimestoneBricks);
		world.setBlock(i + 6, j + 5, k + 24, this.largeLimestoneBricks);
		world.setBlock(i + 6, j + 5, k + 27, this.largeLimestoneBricks);
		world.setBlock(i + 6, j + 5, k + 30, this.largeLimestoneBricks);
		world.setBlock(i + 6, j + 5, k + 33, this.largeLimestoneBricks);
		world.setBlock(i + 6, j + 5, k + 36, this.largeLimestoneBricks);
		world.setBlock(i + 6, j + 5, k + 39, this.largeLimestoneBricks);
		world.setBlock(i + 6, j + 5, k + 42, this.largeLimestoneBricks);
		world.setBlock(i + 6, j + 6, k + 9, this.largeLimestoneBricks);
		world.setBlock(i + 6, j + 6, k + 10, this.largeLimestoneBricks);
		world.setBlock(i + 6, j + 6, k + 11, this.largeLimestoneBricks);
		world.setBlock(i + 6, j + 6, k + 12, this.largeLimestoneBricks);
		world.setBlock(i + 6, j + 6, k + 13, this.largeLimestoneBricks);
		world.setBlock(i + 6, j + 6, k + 14, this.largeLimestoneBricks);
		world.setBlock(i + 6, j + 6, k + 15, this.largeLimestoneBricks);
		world.setBlock(i + 6, j + 6, k + 16, this.largeLimestoneBricks);
		world.setBlock(i + 6, j + 6, k + 17, this.largeLimestoneBricks);
		world.setBlock(i + 6, j + 6, k + 18, this.largeLimestoneBricks);
		world.setBlock(i + 6, j + 6, k + 19, this.largeLimestoneBricks);
		world.setBlock(i + 6, j + 6, k + 20, this.largeLimestoneBricks);
		world.setBlock(i + 6, j + 6, k + 21, this.largeLimestoneBricks);
		world.setBlock(i + 6, j + 6, k + 22, this.largeLimestoneBricks);
		world.setBlock(i + 6, j + 6, k + 23, this.largeLimestoneBricks);
		world.setBlock(i + 6, j + 6, k + 24, this.largeLimestoneBricks);
		world.setBlock(i + 6, j + 6, k + 25, this.largeLimestoneBricks);
		world.setBlock(i + 6, j + 6, k + 26, this.largeLimestoneBricks);
		world.setBlock(i + 6, j + 6, k + 27, this.largeLimestoneBricks);
		world.setBlock(i + 6, j + 6, k + 28, this.largeLimestoneBricks);
		world.setBlock(i + 6, j + 6, k + 29, this.largeLimestoneBricks);
		world.setBlock(i + 6, j + 6, k + 30, this.largeLimestoneBricks);
		world.setBlock(i + 6, j + 6, k + 31, this.largeLimestoneBricks);
		world.setBlock(i + 6, j + 6, k + 32, this.largeLimestoneBricks);
		world.setBlock(i + 6, j + 6, k + 33, this.largeLimestoneBricks);
		world.setBlock(i + 6, j + 6, k + 34, this.largeLimestoneBricks);
		world.setBlock(i + 6, j + 6, k + 35, this.largeLimestoneBricks);
		world.setBlock(i + 6, j + 6, k + 36, this.largeLimestoneBricks);
		world.setBlock(i + 6, j + 6, k + 37, this.largeLimestoneBricks);
		world.setBlock(i + 6, j + 6, k + 38, this.largeLimestoneBricks);
		world.setBlock(i + 6, j + 6, k + 39, this.largeLimestoneBricks);
		world.setBlock(i + 6, j + 6, k + 40, this.largeLimestoneBricks);
		world.setBlock(i + 6, j + 6, k + 41, this.largeLimestoneBricks);
		world.setBlock(i + 6, j + 6, k + 42, this.largeLimestoneBricks);
		world.setBlock(i + 6, j + 6, k + 43, this.largeLimestoneBricks);
		world.setBlock(i + 6, j + 6, k + 44, this.largeLimestoneBricks);
		world.setBlock(i + 6, j + 6, k + 45, this.largeLimestoneBricks);
		world.setBlock(i + 6, j + 6, k + 46, this.largeLimestoneBricks);
		world.setBlock(i + 6, j + 6, k + 47, this.largeLimestoneBricks);
		world.setBlock(i + 6, j + 6, k + 48, this.largeLimestoneBricks);
		world.setBlock(i + 6, j + 7, k + 15, this.largeLimestoneBricks);
		world.setBlock(i + 6, j + 7, k + 18, this.largeLimestoneBricks);
		world.setBlock(i + 6, j + 7, k + 21, this.largeLimestoneBricks);
		world.setBlock(i + 6, j + 7, k + 24, this.largeLimestoneBricks);
		world.setBlock(i + 6, j + 7, k + 27, this.largeLimestoneBricks);
		world.setBlock(i + 6, j + 7, k + 30, this.largeLimestoneBricks);
		world.setBlock(i + 6, j + 7, k + 33, this.largeLimestoneBricks);
		world.setBlock(i + 6, j + 7, k + 36, this.largeLimestoneBricks);
		world.setBlock(i + 6, j + 7, k + 39, this.largeLimestoneBricks);
		world.setBlock(i + 6, j + 7, k + 42, this.largeLimestoneBricks);
		world.setBlock(i + 6, j + 10, k + 15, this.largeLimestoneBricks);
		world.setBlock(i + 6, j + 10, k + 18, this.largeLimestoneBricks);
		world.setBlock(i + 6, j + 10, k + 21, this.largeLimestoneBricks);
		world.setBlock(i + 6, j + 10, k + 24, this.largeLimestoneBricks);
		world.setBlock(i + 6, j + 10, k + 27, this.largeLimestoneBricks);
		world.setBlock(i + 6, j + 10, k + 30, this.largeLimestoneBricks);
		world.setBlock(i + 6, j + 10, k + 33, this.largeLimestoneBricks);
		world.setBlock(i + 6, j + 10, k + 36, this.largeLimestoneBricks);
		world.setBlock(i + 6, j + 10, k + 39, this.largeLimestoneBricks);
		world.setBlock(i + 6, j + 10, k + 42, this.largeLimestoneBricks);
		world.setBlock(i + 6, j + 11, k + 14, this.largeLimestoneBricks);
		world.setBlock(i + 6, j + 11, k + 15, this.largeLimestoneBricks);
		world.setBlock(i + 6, j + 11, k + 16, this.largeLimestoneBricks);
		world.setBlock(i + 6, j + 11, k + 17, this.largeLimestoneBricks);
		world.setBlock(i + 6, j + 11, k + 18, this.largeLimestoneBricks);
		world.setBlock(i + 6, j + 11, k + 19, this.largeLimestoneBricks);
		world.setBlock(i + 6, j + 11, k + 20, this.largeLimestoneBricks);
		world.setBlock(i + 6, j + 11, k + 21, this.largeLimestoneBricks);
		world.setBlock(i + 6, j + 11, k + 22, this.largeLimestoneBricks);
		world.setBlock(i + 6, j + 11, k + 23, this.largeLimestoneBricks);
		world.setBlock(i + 6, j + 11, k + 24, this.largeLimestoneBricks);
		world.setBlock(i + 6, j + 11, k + 25, this.largeLimestoneBricks);
		world.setBlock(i + 6, j + 11, k + 26, this.largeLimestoneBricks);
		world.setBlock(i + 6, j + 11, k + 27, this.largeLimestoneBricks);
		world.setBlock(i + 6, j + 11, k + 28, this.largeLimestoneBricks);
		world.setBlock(i + 6, j + 11, k + 29, this.largeLimestoneBricks);
		world.setBlock(i + 6, j + 11, k + 30, this.largeLimestoneBricks);
		world.setBlock(i + 6, j + 11, k + 31, this.largeLimestoneBricks);
		world.setBlock(i + 6, j + 11, k + 32, this.largeLimestoneBricks);
		world.setBlock(i + 6, j + 11, k + 33, this.largeLimestoneBricks);
		world.setBlock(i + 6, j + 11, k + 34, this.largeLimestoneBricks);
		world.setBlock(i + 6, j + 11, k + 35, this.largeLimestoneBricks);
		world.setBlock(i + 6, j + 11, k + 36, this.largeLimestoneBricks);
		world.setBlock(i + 6, j + 11, k + 37, this.largeLimestoneBricks);
		world.setBlock(i + 6, j + 11, k + 38, this.largeLimestoneBricks);
		world.setBlock(i + 6, j + 11, k + 39, this.largeLimestoneBricks);
		world.setBlock(i + 6, j + 11, k + 40, this.largeLimestoneBricks);
		world.setBlock(i + 6, j + 11, k + 41, this.largeLimestoneBricks);
		world.setBlock(i + 6, j + 11, k + 42, this.largeLimestoneBricks);
		world.setBlock(i + 6, j + 11, k + 43, this.largeLimestoneBricks);
		world.setBlock(i + 7, j + 0, k + 8, this.largeLimestoneBricks);
		world.setBlock(i + 7, j + 0, k + 49, this.largeLimestoneBricks);
		world.setBlock(i + 7, j + 1, k + 8, this.largeLimestoneBricks);
		world.setBlock(i + 7, j + 1, k + 9, this.largeLimestoneBricks);
		world.setBlock(i + 7, j + 1, k + 10, this.largeLimestoneBricks);
		world.setBlock(i + 7, j + 1, k + 11, this.largeLimestoneBricks);
		world.setBlock(i + 7, j + 1, k + 12, this.largeLimestoneBricks);
		world.setBlock(i + 7, j + 1, k + 13, this.largeLimestoneBricks);
		world.setBlock(i + 7, j + 1, k + 14, this.largeLimestoneBricks);
		world.setBlock(i + 7, j + 1, k + 15, this.largeLimestoneBricks);
		world.setBlock(i + 7, j + 1, k + 16, this.largeLimestoneBricks);
		world.setBlock(i + 7, j + 1, k + 17, this.largeLimestoneBricks);
		world.setBlock(i + 7, j + 1, k + 18, this.largeLimestoneBricks);
		world.setBlock(i + 7, j + 1, k + 19, this.largeLimestoneBricks);
		world.setBlock(i + 7, j + 1, k + 20, this.largeLimestoneBricks);
		world.setBlock(i + 7, j + 1, k + 21, this.largeLimestoneBricks);
		world.setBlock(i + 7, j + 1, k + 22, this.largeLimestoneBricks);
		world.setBlock(i + 7, j + 1, k + 23, this.largeLimestoneBricks);
		world.setBlock(i + 7, j + 1, k + 24, this.largeLimestoneBricks);
		world.setBlock(i + 7, j + 1, k + 25, this.largeLimestoneBricks);
		world.setBlock(i + 7, j + 1, k + 26, this.largeLimestoneBricks);
		world.setBlock(i + 7, j + 1, k + 27, this.largeLimestoneBricks);
		world.setBlock(i + 7, j + 1, k + 28, this.largeLimestoneBricks);
		world.setBlock(i + 7, j + 1, k + 29, this.largeLimestoneBricks);
		world.setBlock(i + 7, j + 1, k + 30, this.largeLimestoneBricks);
		world.setBlock(i + 7, j + 1, k + 31, this.largeLimestoneBricks);
		world.setBlock(i + 7, j + 1, k + 32, this.largeLimestoneBricks);
		world.setBlock(i + 7, j + 1, k + 33, this.largeLimestoneBricks);
		world.setBlock(i + 7, j + 1, k + 34, this.largeLimestoneBricks);
		world.setBlock(i + 7, j + 1, k + 35, this.largeLimestoneBricks);
		world.setBlock(i + 7, j + 1, k + 36, this.largeLimestoneBricks);
		world.setBlock(i + 7, j + 1, k + 37, this.largeLimestoneBricks);
		world.setBlock(i + 7, j + 1, k + 38, this.largeLimestoneBricks);
		world.setBlock(i + 7, j + 1, k + 39, this.largeLimestoneBricks);
		world.setBlock(i + 7, j + 1, k + 40, this.largeLimestoneBricks);
		world.setBlock(i + 7, j + 1, k + 41, this.largeLimestoneBricks);
		world.setBlock(i + 7, j + 1, k + 42, this.largeLimestoneBricks);
		world.setBlock(i + 7, j + 1, k + 43, this.largeLimestoneBricks);
		world.setBlock(i + 7, j + 1, k + 44, this.largeLimestoneBricks);
		world.setBlock(i + 7, j + 1, k + 45, this.largeLimestoneBricks);
		world.setBlock(i + 7, j + 1, k + 46, this.largeLimestoneBricks);
		world.setBlock(i + 7, j + 1, k + 47, this.largeLimestoneBricks);
		world.setBlock(i + 7, j + 1, k + 48, this.largeLimestoneBricks);
		world.setBlock(i + 7, j + 1, k + 49, this.largeLimestoneBricks);
		world.setBlock(i + 7, j + 2, k + 9, this.largeLimestoneBricks);
		world.setBlock(i + 7, j + 2, k + 14, this.largeLimestoneBricks);
		world.setBlock(i + 7, j + 2, k + 15, this.largeLimestoneBricks);
		world.setBlock(i + 7, j + 2, k + 16, this.largeLimestoneBricks);
		world.setBlock(i + 7, j + 2, k + 17, this.largeLimestoneBricks);
		world.setBlock(i + 7, j + 2, k + 18, this.largeLimestoneBricks);
		world.setBlock(i + 7, j + 2, k + 19, this.largeLimestoneBricks);
		world.setBlock(i + 7, j + 2, k + 20, this.largeLimestoneBricks);
		world.setBlock(i + 7, j + 2, k + 21, this.largeLimestoneBricks);
		world.setBlock(i + 7, j + 2, k + 22, this.largeLimestoneBricks);
		world.setBlock(i + 7, j + 2, k + 23, this.largeLimestoneBricks);
		world.setBlock(i + 7, j + 2, k + 24, this.largeLimestoneBricks);
		world.setBlock(i + 7, j + 2, k + 25, this.largeLimestoneBricks);
		world.setBlock(i + 7, j + 2, k + 26, this.largeLimestoneBricks);
		world.setBlock(i + 7, j + 2, k + 27, this.largeLimestoneBricks);
		world.setBlock(i + 7, j + 2, k + 28, this.largeLimestoneBricks);
		world.setBlock(i + 7, j + 2, k + 29, this.largeLimestoneBricks);
		world.setBlock(i + 7, j + 2, k + 30, this.largeLimestoneBricks);
		world.setBlock(i + 7, j + 2, k + 31, this.largeLimestoneBricks);
		world.setBlock(i + 7, j + 2, k + 32, this.largeLimestoneBricks);
		world.setBlock(i + 7, j + 2, k + 33, this.largeLimestoneBricks);
		world.setBlock(i + 7, j + 2, k + 34, this.largeLimestoneBricks);
		world.setBlock(i + 7, j + 2, k + 35, this.largeLimestoneBricks);
		world.setBlock(i + 7, j + 2, k + 36, this.largeLimestoneBricks);
		world.setBlock(i + 7, j + 2, k + 37, this.largeLimestoneBricks);
		world.setBlock(i + 7, j + 2, k + 38, this.largeLimestoneBricks);
		world.setBlock(i + 7, j + 2, k + 39, this.largeLimestoneBricks);
		world.setBlock(i + 7, j + 2, k + 40, this.largeLimestoneBricks);
		world.setBlock(i + 7, j + 2, k + 41, this.largeLimestoneBricks);
		world.setBlock(i + 7, j + 2, k + 42, this.largeLimestoneBricks);
		world.setBlock(i + 7, j + 2, k + 43, this.largeLimestoneBricks);
		world.setBlock(i + 7, j + 2, k + 48, this.largeLimestoneBricks);
		world.setBlock(i + 7, j + 3, k + 15, this.largeLimestoneBricks);
		world.setBlock(i + 7, j + 3, k + 16, this.largeLimestoneBricks);
		world.setBlock(i + 7, j + 3, k + 17, this.largeLimestoneBricks);
		world.setBlock(i + 7, j + 3, k + 18, this.largeLimestoneBricks);
		world.setBlock(i + 7, j + 3, k + 19, this.largeLimestoneBricks);
		world.setBlock(i + 7, j + 3, k + 20, this.largeLimestoneBricks);
		world.setBlock(i + 7, j + 3, k + 21, this.largeLimestoneBricks);
		world.setBlock(i + 7, j + 3, k + 22, this.largeLimestoneBricks);
		world.setBlock(i + 7, j + 3, k + 23, this.largeLimestoneBricks);
		world.setBlock(i + 7, j + 3, k + 24, this.largeLimestoneBricks);
		world.setBlock(i + 7, j + 3, k + 25, this.largeLimestoneBricks);
		world.setBlock(i + 7, j + 3, k + 26, this.largeLimestoneBricks);
		world.setBlock(i + 7, j + 3, k + 27, this.largeLimestoneBricks);
		world.setBlock(i + 7, j + 3, k + 28, this.largeLimestoneBricks);
		world.setBlock(i + 7, j + 3, k + 29, this.largeLimestoneBricks);
		world.setBlock(i + 7, j + 3, k + 30, this.largeLimestoneBricks);
		world.setBlock(i + 7, j + 3, k + 31, this.largeLimestoneBricks);
		world.setBlock(i + 7, j + 3, k + 32, this.largeLimestoneBricks);
		world.setBlock(i + 7, j + 3, k + 33, this.largeLimestoneBricks);
		world.setBlock(i + 7, j + 3, k + 34, this.largeLimestoneBricks);
		world.setBlock(i + 7, j + 3, k + 35, this.largeLimestoneBricks);
		world.setBlock(i + 7, j + 3, k + 36, this.largeLimestoneBricks);
		world.setBlock(i + 7, j + 3, k + 37, this.largeLimestoneBricks);
		world.setBlock(i + 7, j + 3, k + 38, this.largeLimestoneBricks);
		world.setBlock(i + 7, j + 3, k + 39, this.largeLimestoneBricks);
		world.setBlock(i + 7, j + 3, k + 40, this.largeLimestoneBricks);
		world.setBlock(i + 7, j + 3, k + 41, this.largeLimestoneBricks);
		world.setBlock(i + 7, j + 3, k + 42, this.largeLimestoneBricks);
		world.setBlock(i + 7, j + 4, k + 15, this.largeLimestoneBricks);
		world.setBlock(i + 7, j + 4, k + 16, this.largeLimestoneBricks);
		world.setBlock(i + 7, j + 4, k + 17, this.largeLimestoneBricks);
		world.setBlock(i + 7, j + 4, k + 18, this.largeLimestoneBricks);
		world.setBlock(i + 7, j + 4, k + 19, this.largeLimestoneBricks);
		world.setBlock(i + 7, j + 4, k + 20, this.largeLimestoneBricks);
		world.setBlock(i + 7, j + 4, k + 21, this.largeLimestoneBricks);
		world.setBlock(i + 7, j + 4, k + 22, this.largeLimestoneBricks);
		world.setBlock(i + 7, j + 4, k + 23, this.largeLimestoneBricks);
		world.setBlock(i + 7, j + 4, k + 24, this.largeLimestoneBricks);
		world.setBlock(i + 7, j + 4, k + 25, this.largeLimestoneBricks);
		world.setBlock(i + 7, j + 4, k + 26, this.largeLimestoneBricks);
		world.setBlock(i + 7, j + 4, k + 27, this.largeLimestoneBricks);
		world.setBlock(i + 7, j + 4, k + 28, this.largeLimestoneBricks);
		world.setBlock(i + 7, j + 4, k + 29, this.largeLimestoneBricks);
		world.setBlock(i + 7, j + 4, k + 30, this.largeLimestoneBricks);
		world.setBlock(i + 7, j + 4, k + 31, this.largeLimestoneBricks);
		world.setBlock(i + 7, j + 4, k + 32, this.largeLimestoneBricks);
		world.setBlock(i + 7, j + 4, k + 33, this.largeLimestoneBricks);
		world.setBlock(i + 7, j + 4, k + 34, this.largeLimestoneBricks);
		world.setBlock(i + 7, j + 4, k + 35, this.largeLimestoneBricks);
		world.setBlock(i + 7, j + 4, k + 36, this.largeLimestoneBricks);
		world.setBlock(i + 7, j + 4, k + 37, this.largeLimestoneBricks);
		world.setBlock(i + 7, j + 4, k + 38, this.largeLimestoneBricks);
		world.setBlock(i + 7, j + 4, k + 39, this.largeLimestoneBricks);
		world.setBlock(i + 7, j + 4, k + 40, this.largeLimestoneBricks);
		world.setBlock(i + 7, j + 4, k + 41, this.largeLimestoneBricks);
		world.setBlock(i + 7, j + 4, k + 42, this.largeLimestoneBricks);
		world.setBlock(i + 7, j + 5, k + 9, this.largeLimestoneBricks);
		world.setBlock(i + 7, j + 5, k + 14, this.largeLimestoneBricks);
		world.setBlock(i + 7, j + 5, k + 15, this.largeLimestoneBricks);
		world.setBlock(i + 7, j + 5, k + 16, this.largeLimestoneBricks);
		world.setBlock(i + 7, j + 5, k + 17, this.largeLimestoneBricks);
		world.setBlock(i + 7, j + 5, k + 18, this.largeLimestoneBricks);
		world.setBlock(i + 7, j + 5, k + 19, this.largeLimestoneBricks);
		world.setBlock(i + 7, j + 5, k + 20, this.largeLimestoneBricks);
		world.setBlock(i + 7, j + 5, k + 21, this.largeLimestoneBricks);
		world.setBlock(i + 7, j + 5, k + 22, this.largeLimestoneBricks);
		world.setBlock(i + 7, j + 5, k + 23, this.largeLimestoneBricks);
		world.setBlock(i + 7, j + 5, k + 24, this.largeLimestoneBricks);
		world.setBlock(i + 7, j + 5, k + 25, this.largeLimestoneBricks);
		world.setBlock(i + 7, j + 5, k + 26, this.largeLimestoneBricks);
		world.setBlock(i + 7, j + 5, k + 27, this.largeLimestoneBricks);
		world.setBlock(i + 7, j + 5, k + 28, this.largeLimestoneBricks);
		world.setBlock(i + 7, j + 5, k + 29, this.largeLimestoneBricks);
		world.setBlock(i + 7, j + 5, k + 30, this.largeLimestoneBricks);
		world.setBlock(i + 7, j + 5, k + 31, this.largeLimestoneBricks);
		world.setBlock(i + 7, j + 5, k + 32, this.largeLimestoneBricks);
		world.setBlock(i + 7, j + 5, k + 33, this.largeLimestoneBricks);
		world.setBlock(i + 7, j + 5, k + 34, this.largeLimestoneBricks);
		world.setBlock(i + 7, j + 5, k + 35, this.largeLimestoneBricks);
		world.setBlock(i + 7, j + 5, k + 36, this.largeLimestoneBricks);
		world.setBlock(i + 7, j + 5, k + 37, this.largeLimestoneBricks);
		world.setBlock(i + 7, j + 5, k + 38, this.largeLimestoneBricks);
		world.setBlock(i + 7, j + 5, k + 39, this.largeLimestoneBricks);
		world.setBlock(i + 7, j + 5, k + 40, this.largeLimestoneBricks);
		world.setBlock(i + 7, j + 5, k + 41, this.largeLimestoneBricks);
		world.setBlock(i + 7, j + 5, k + 42, this.largeLimestoneBricks);
		world.setBlock(i + 7, j + 5, k + 43, this.largeLimestoneBricks);
		world.setBlock(i + 7, j + 5, k + 48, this.largeLimestoneBricks);
		world.setBlock(i + 7, j + 6, k + 9, this.largeLimestoneBricks);
		world.setBlock(i + 7, j + 6, k + 10, this.largeLimestoneBricks);
		world.setBlock(i + 7, j + 6, k + 11, this.largeLimestoneBricks);
		world.setBlock(i + 7, j + 6, k + 12, this.largeLimestoneBricks);
		world.setBlock(i + 7, j + 6, k + 13, this.largeLimestoneBricks);
		world.setBlock(i + 7, j + 6, k + 14, this.largeLimestoneBricks);
		world.setBlock(i + 7, j + 6, k + 15, this.largeLimestoneBricks);
		world.setBlock(i + 7, j + 6, k + 16, this.largeLimestoneBricks);
		world.setBlock(i + 7, j + 6, k + 17, this.largeLimestoneBricks);
		world.setBlock(i + 7, j + 6, k + 18, this.largeLimestoneBricks);
		world.setBlock(i + 7, j + 6, k + 19, this.largeLimestoneBricks);
		world.setBlock(i + 7, j + 6, k + 20, this.largeLimestoneBricks);
		world.setBlock(i + 7, j + 6, k + 21, this.largeLimestoneBricks);
		world.setBlock(i + 7, j + 6, k + 22, this.largeLimestoneBricks);
		world.setBlock(i + 7, j + 6, k + 23, this.largeLimestoneBricks);
		world.setBlock(i + 7, j + 6, k + 24, this.largeLimestoneBricks);
		world.setBlock(i + 7, j + 6, k + 25, this.largeLimestoneBricks);
		world.setBlock(i + 7, j + 6, k + 26, this.largeLimestoneBricks);
		world.setBlock(i + 7, j + 6, k + 27, this.largeLimestoneBricks);
		world.setBlock(i + 7, j + 6, k + 28, this.largeLimestoneBricks);
		world.setBlock(i + 7, j + 6, k + 29, this.largeLimestoneBricks);
		world.setBlock(i + 7, j + 6, k + 30, this.largeLimestoneBricks);
		world.setBlock(i + 7, j + 6, k + 31, this.largeLimestoneBricks);
		world.setBlock(i + 7, j + 6, k + 32, this.largeLimestoneBricks);
		world.setBlock(i + 7, j + 6, k + 33, this.largeLimestoneBricks);
		world.setBlock(i + 7, j + 6, k + 34, this.largeLimestoneBricks);
		world.setBlock(i + 7, j + 6, k + 35, this.largeLimestoneBricks);
		world.setBlock(i + 7, j + 6, k + 36, this.largeLimestoneBricks);
		world.setBlock(i + 7, j + 6, k + 37, this.largeLimestoneBricks);
		world.setBlock(i + 7, j + 6, k + 38, this.largeLimestoneBricks);
		world.setBlock(i + 7, j + 6, k + 39, this.largeLimestoneBricks);
		world.setBlock(i + 7, j + 6, k + 40, this.largeLimestoneBricks);
		world.setBlock(i + 7, j + 6, k + 41, this.largeLimestoneBricks);
		world.setBlock(i + 7, j + 6, k + 42, this.largeLimestoneBricks);
		world.setBlock(i + 7, j + 6, k + 43, this.largeLimestoneBricks);
		world.setBlock(i + 7, j + 6, k + 44, this.largeLimestoneBricks);
		world.setBlock(i + 7, j + 6, k + 45, this.largeLimestoneBricks);
		world.setBlock(i + 7, j + 6, k + 46, this.largeLimestoneBricks);
		world.setBlock(i + 7, j + 6, k + 47, this.largeLimestoneBricks);
		world.setBlock(i + 7, j + 6, k + 48, this.largeLimestoneBricks);
		world.setBlock(i + 7, j + 7, k + 14, this.largeLimestoneBricks);
		world.setBlock(i + 7, j + 7, k + 15, this.largeLimestoneBricks);
		world.setBlock(i + 7, j + 7, k + 16, this.largeLimestoneBricks);
		world.setBlock(i + 7, j + 7, k + 17, this.largeLimestoneBricks);
		world.setBlock(i + 7, j + 7, k + 18, this.largeLimestoneBricks);
		world.setBlock(i + 7, j + 7, k + 19, this.largeLimestoneBricks);
		world.setBlock(i + 7, j + 7, k + 20, this.largeLimestoneBricks);
		world.setBlock(i + 7, j + 7, k + 21, this.largeLimestoneBricks);
		world.setBlock(i + 7, j + 7, k + 22, this.largeLimestoneBricks);
		world.setBlock(i + 7, j + 7, k + 23, this.largeLimestoneBricks);
		world.setBlock(i + 7, j + 7, k + 24, this.largeLimestoneBricks);
		world.setBlock(i + 7, j + 7, k + 25, this.largeLimestoneBricks);
		world.setBlock(i + 7, j + 7, k + 26, this.largeLimestoneBricks);
		world.setBlock(i + 7, j + 7, k + 27, this.largeLimestoneBricks);
		world.setBlock(i + 7, j + 7, k + 28, this.largeLimestoneBricks);
		world.setBlock(i + 7, j + 7, k + 29, this.largeLimestoneBricks);
		world.setBlock(i + 7, j + 7, k + 30, this.largeLimestoneBricks);
		world.setBlock(i + 7, j + 7, k + 31, this.largeLimestoneBricks);
		world.setBlock(i + 7, j + 7, k + 32, this.largeLimestoneBricks);
		world.setBlock(i + 7, j + 7, k + 33, this.largeLimestoneBricks);
		world.setBlock(i + 7, j + 7, k + 34, this.largeLimestoneBricks);
		world.setBlock(i + 7, j + 7, k + 35, this.largeLimestoneBricks);
		world.setBlock(i + 7, j + 7, k + 36, this.largeLimestoneBricks);
		world.setBlock(i + 7, j + 7, k + 37, this.largeLimestoneBricks);
		world.setBlock(i + 7, j + 7, k + 38, this.largeLimestoneBricks);
		world.setBlock(i + 7, j + 7, k + 39, this.largeLimestoneBricks);
		world.setBlock(i + 7, j + 7, k + 40, this.largeLimestoneBricks);
		world.setBlock(i + 7, j + 7, k + 41, this.largeLimestoneBricks);
		world.setBlock(i + 7, j + 7, k + 42, this.largeLimestoneBricks);
		world.setBlock(i + 7, j + 7, k + 43, this.largeLimestoneBricks);
		world.setBlock(i + 7, j + 8, k + 15, this.largeLimestoneBricks);
		world.setBlock(i + 7, j + 8, k + 16, this.largeLimestoneBricks);
		world.setBlock(i + 7, j + 8, k + 17, this.largeLimestoneBricks);
		world.setBlock(i + 7, j + 8, k + 18, this.largeLimestoneBricks);
		world.setBlock(i + 7, j + 8, k + 19, this.largeLimestoneBricks);
		world.setBlock(i + 7, j + 8, k + 20, this.largeLimestoneBricks);
		world.setBlock(i + 7, j + 8, k + 21, this.largeLimestoneBricks);
		world.setBlock(i + 7, j + 8, k + 22, this.largeLimestoneBricks);
		world.setBlock(i + 7, j + 8, k + 23, this.largeLimestoneBricks);
		world.setBlock(i + 7, j + 8, k + 24, this.largeLimestoneBricks);
		world.setBlock(i + 7, j + 8, k + 25, this.largeLimestoneBricks);
		world.setBlock(i + 7, j + 8, k + 26, this.largeLimestoneBricks);
		world.setBlock(i + 7, j + 8, k + 27, this.largeLimestoneBricks);
		world.setBlock(i + 7, j + 8, k + 28, this.largeLimestoneBricks);
		world.setBlock(i + 7, j + 8, k + 29, this.largeLimestoneBricks);
		world.setBlock(i + 7, j + 8, k + 30, this.largeLimestoneBricks);
		world.setBlock(i + 7, j + 8, k + 31, this.largeLimestoneBricks);
		world.setBlock(i + 7, j + 8, k + 32, this.largeLimestoneBricks);
		world.setBlock(i + 7, j + 8, k + 33, this.largeLimestoneBricks);
		world.setBlock(i + 7, j + 8, k + 34, this.largeLimestoneBricks);
		world.setBlock(i + 7, j + 8, k + 35, this.largeLimestoneBricks);
		world.setBlock(i + 7, j + 8, k + 36, this.largeLimestoneBricks);
		world.setBlock(i + 7, j + 8, k + 37, this.largeLimestoneBricks);
		world.setBlock(i + 7, j + 8, k + 38, this.largeLimestoneBricks);
		world.setBlock(i + 7, j + 8, k + 39, this.largeLimestoneBricks);
		world.setBlock(i + 7, j + 8, k + 40, this.largeLimestoneBricks);
		world.setBlock(i + 7, j + 8, k + 41, this.largeLimestoneBricks);
		world.setBlock(i + 7, j + 8, k + 42, this.largeLimestoneBricks);
		world.setBlock(i + 7, j + 9, k + 15, this.largeLimestoneBricks);
		world.setBlock(i + 7, j + 9, k + 16, this.largeLimestoneBricks);
		world.setBlock(i + 7, j + 9, k + 17, this.largeLimestoneBricks);
		world.setBlock(i + 7, j + 9, k + 18, this.largeLimestoneBricks);
		world.setBlock(i + 7, j + 9, k + 19, this.largeLimestoneBricks);
		world.setBlock(i + 7, j + 9, k + 20, this.largeLimestoneBricks);
		world.setBlock(i + 7, j + 9, k + 21, this.largeLimestoneBricks);
		world.setBlock(i + 7, j + 9, k + 22, this.largeLimestoneBricks);
		world.setBlock(i + 7, j + 9, k + 23, this.largeLimestoneBricks);
		world.setBlock(i + 7, j + 9, k + 24, this.largeLimestoneBricks);
		world.setBlock(i + 7, j + 9, k + 25, this.largeLimestoneBricks);
		world.setBlock(i + 7, j + 9, k + 26, this.largeLimestoneBricks);
		world.setBlock(i + 7, j + 9, k + 27, this.largeLimestoneBricks);
		world.setBlock(i + 7, j + 9, k + 28, this.largeLimestoneBricks);
		world.setBlock(i + 7, j + 9, k + 29, this.largeLimestoneBricks);
		world.setBlock(i + 7, j + 9, k + 30, this.largeLimestoneBricks);
		world.setBlock(i + 7, j + 9, k + 31, this.largeLimestoneBricks);
		world.setBlock(i + 7, j + 9, k + 32, this.largeLimestoneBricks);
		world.setBlock(i + 7, j + 9, k + 33, this.largeLimestoneBricks);
		world.setBlock(i + 7, j + 9, k + 34, this.largeLimestoneBricks);
		world.setBlock(i + 7, j + 9, k + 35, this.largeLimestoneBricks);
		world.setBlock(i + 7, j + 9, k + 36, this.largeLimestoneBricks);
		world.setBlock(i + 7, j + 9, k + 37, this.largeLimestoneBricks);
		world.setBlock(i + 7, j + 9, k + 38, this.largeLimestoneBricks);
		world.setBlock(i + 7, j + 9, k + 39, this.largeLimestoneBricks);
		world.setBlock(i + 7, j + 9, k + 40, this.largeLimestoneBricks);
		world.setBlock(i + 7, j + 9, k + 41, this.largeLimestoneBricks);
		world.setBlock(i + 7, j + 9, k + 42, this.largeLimestoneBricks);
		world.setBlock(i + 7, j + 10, k + 14, this.largeLimestoneBricks);
		world.setBlock(i + 7, j + 10, k + 15, this.largeLimestoneBricks);
		world.setBlock(i + 7, j + 10, k + 16, this.largeLimestoneBricks);
		world.setBlock(i + 7, j + 10, k + 17, this.largeLimestoneBricks);
		world.setBlock(i + 7, j + 10, k + 18, this.largeLimestoneBricks);
		world.setBlock(i + 7, j + 10, k + 19, this.largeLimestoneBricks);
		world.setBlock(i + 7, j + 10, k + 20, this.largeLimestoneBricks);
		world.setBlock(i + 7, j + 10, k + 21, this.largeLimestoneBricks);
		world.setBlock(i + 7, j + 10, k + 22, this.largeLimestoneBricks);
		world.setBlock(i + 7, j + 10, k + 23, this.largeLimestoneBricks);
		world.setBlock(i + 7, j + 10, k + 24, this.largeLimestoneBricks);
		world.setBlock(i + 7, j + 10, k + 25, this.largeLimestoneBricks);
		world.setBlock(i + 7, j + 10, k + 26, this.largeLimestoneBricks);
		world.setBlock(i + 7, j + 10, k + 27, this.largeLimestoneBricks);
		world.setBlock(i + 7, j + 10, k + 28, this.largeLimestoneBricks);
		world.setBlock(i + 7, j + 10, k + 29, this.largeLimestoneBricks);
		world.setBlock(i + 7, j + 10, k + 30, this.largeLimestoneBricks);
		world.setBlock(i + 7, j + 10, k + 31, this.largeLimestoneBricks);
		world.setBlock(i + 7, j + 10, k + 32, this.largeLimestoneBricks);
		world.setBlock(i + 7, j + 10, k + 33, this.largeLimestoneBricks);
		world.setBlock(i + 7, j + 10, k + 34, this.largeLimestoneBricks);
		world.setBlock(i + 7, j + 10, k + 35, this.largeLimestoneBricks);
		world.setBlock(i + 7, j + 10, k + 36, this.largeLimestoneBricks);
		world.setBlock(i + 7, j + 10, k + 37, this.largeLimestoneBricks);
		world.setBlock(i + 7, j + 10, k + 38, this.largeLimestoneBricks);
		world.setBlock(i + 7, j + 10, k + 39, this.largeLimestoneBricks);
		world.setBlock(i + 7, j + 10, k + 40, this.largeLimestoneBricks);
		world.setBlock(i + 7, j + 10, k + 41, this.largeLimestoneBricks);
		world.setBlock(i + 7, j + 10, k + 42, this.largeLimestoneBricks);
		world.setBlock(i + 7, j + 10, k + 43, this.largeLimestoneBricks);
		world.setBlock(i + 7, j + 11, k + 14, this.largeLimestoneBricks);
		world.setBlock(i + 7, j + 11, k + 15, this.largeLimestoneBricks);
		world.setBlock(i + 7, j + 11, k + 16, this.largeLimestoneBricks);
		world.setBlock(i + 7, j + 11, k + 17, this.largeLimestoneBricks);
		world.setBlock(i + 7, j + 11, k + 18, this.largeLimestoneBricks);
		world.setBlock(i + 7, j + 11, k + 19, this.largeLimestoneBricks);
		world.setBlock(i + 7, j + 11, k + 20, this.largeLimestoneBricks);
		world.setBlock(i + 7, j + 11, k + 21, this.largeLimestoneBricks);
		world.setBlock(i + 7, j + 11, k + 22, this.largeLimestoneBricks);
		world.setBlock(i + 7, j + 11, k + 23, this.largeLimestoneBricks);
		world.setBlock(i + 7, j + 11, k + 24, this.largeLimestoneBricks);
		world.setBlock(i + 7, j + 11, k + 25, this.largeLimestoneBricks);
		world.setBlock(i + 7, j + 11, k + 26, this.largeLimestoneBricks);
		world.setBlock(i + 7, j + 11, k + 27, this.largeLimestoneBricks);
		world.setBlock(i + 7, j + 11, k + 28, this.largeLimestoneBricks);
		world.setBlock(i + 7, j + 11, k + 29, this.largeLimestoneBricks);
		world.setBlock(i + 7, j + 11, k + 30, this.largeLimestoneBricks);
		world.setBlock(i + 7, j + 11, k + 31, this.largeLimestoneBricks);
		world.setBlock(i + 7, j + 11, k + 32, this.largeLimestoneBricks);
		world.setBlock(i + 7, j + 11, k + 33, this.largeLimestoneBricks);
		world.setBlock(i + 7, j + 11, k + 34, this.largeLimestoneBricks);
		world.setBlock(i + 7, j + 11, k + 35, this.largeLimestoneBricks);
		world.setBlock(i + 7, j + 11, k + 36, this.largeLimestoneBricks);
		world.setBlock(i + 7, j + 11, k + 37, this.largeLimestoneBricks);
		world.setBlock(i + 7, j + 11, k + 38, this.largeLimestoneBricks);
		world.setBlock(i + 7, j + 11, k + 39, this.largeLimestoneBricks);
		world.setBlock(i + 7, j + 11, k + 40, this.largeLimestoneBricks);
		world.setBlock(i + 7, j + 11, k + 41, this.largeLimestoneBricks);
		world.setBlock(i + 7, j + 11, k + 42, this.largeLimestoneBricks);
		world.setBlock(i + 7, j + 11, k + 43, this.largeLimestoneBricks);
		world.setBlock(i + 8, j + 0, k + 8, this.largeLimestoneBricks);
		world.setBlock(i + 8, j + 0, k + 49, this.largeLimestoneBricks);
		world.setBlock(i + 8, j + 1, k + 8, this.largeLimestoneBricks);
		world.setBlock(i + 8, j + 1, k + 9, this.largeLimestoneBricks);
		world.setBlock(i + 8, j + 1, k + 10, this.largeLimestoneBricks);
		world.setBlock(i + 8, j + 1, k + 11, this.largeLimestoneBricks);
		world.setBlock(i + 8, j + 1, k + 12, this.largeLimestoneBricks);
		world.setBlock(i + 8, j + 1, k + 13, this.largeLimestoneBricks);
		world.setBlock(i + 8, j + 1, k + 14, this.largeLimestoneBricks);
		world.setBlock(i + 8, j + 1, k + 15, this.largeLimestoneBricks);
		world.setBlock(i + 8, j + 1, k + 16, this.largeLimestoneBricks);
		world.setBlock(i + 8, j + 1, k + 17, this.largeLimestoneBricks);
		world.setBlock(i + 8, j + 1, k + 18, this.largeLimestoneBricks);
		world.setBlock(i + 8, j + 1, k + 19, this.largeLimestoneBricks);
		world.setBlock(i + 8, j + 1, k + 20, this.largeLimestoneBricks);
		world.setBlock(i + 8, j + 1, k + 21, this.largeLimestoneBricks);
		world.setBlock(i + 8, j + 1, k + 22, this.largeLimestoneBricks);
		world.setBlock(i + 8, j + 1, k + 23, this.largeLimestoneBricks);
		world.setBlock(i + 8, j + 1, k + 24, this.largeLimestoneBricks);
		world.setBlock(i + 8, j + 1, k + 25, this.largeLimestoneBricks);
		world.setBlock(i + 8, j + 1, k + 26, this.largeLimestoneBricks);
		world.setBlock(i + 8, j + 1, k + 27, this.largeLimestoneBricks);
		world.setBlock(i + 8, j + 1, k + 28, this.largeLimestoneBricks);
		world.setBlock(i + 8, j + 1, k + 29, this.largeLimestoneBricks);
		world.setBlock(i + 8, j + 1, k + 30, this.largeLimestoneBricks);
		world.setBlock(i + 8, j + 1, k + 31, this.largeLimestoneBricks);
		world.setBlock(i + 8, j + 1, k + 32, this.largeLimestoneBricks);
		world.setBlock(i + 8, j + 1, k + 33, this.largeLimestoneBricks);
		world.setBlock(i + 8, j + 1, k + 34, this.largeLimestoneBricks);
		world.setBlock(i + 8, j + 1, k + 35, this.largeLimestoneBricks);
		world.setBlock(i + 8, j + 1, k + 36, this.largeLimestoneBricks);
		world.setBlock(i + 8, j + 1, k + 37, this.largeLimestoneBricks);
		world.setBlock(i + 8, j + 1, k + 38, this.largeLimestoneBricks);
		world.setBlock(i + 8, j + 1, k + 39, this.largeLimestoneBricks);
		world.setBlock(i + 8, j + 1, k + 40, this.largeLimestoneBricks);
		world.setBlock(i + 8, j + 1, k + 41, this.largeLimestoneBricks);
		world.setBlock(i + 8, j + 1, k + 42, this.largeLimestoneBricks);
		world.setBlock(i + 8, j + 1, k + 43, this.largeLimestoneBricks);
		world.setBlock(i + 8, j + 1, k + 44, this.largeLimestoneBricks);
		world.setBlock(i + 8, j + 1, k + 45, this.largeLimestoneBricks);
		world.setBlock(i + 8, j + 1, k + 46, this.largeLimestoneBricks);
		world.setBlock(i + 8, j + 1, k + 47, this.largeLimestoneBricks);
		world.setBlock(i + 8, j + 1, k + 48, this.largeLimestoneBricks);
		world.setBlock(i + 8, j + 1, k + 49, this.largeLimestoneBricks);
		world.setBlock(i + 8, j + 2, k + 15, this.largeLimestoneBricks);
		world.setBlock(i + 8, j + 2, k + 37, this.largeLimestoneBricks);
		world.setBlock(i + 8, j + 2, k + 38, this.largeLimestoneBricks);
		world.setBlock(i + 8, j + 2, k + 39, this.largeLimestoneBricks);
		world.setBlock(i + 8, j + 2, k + 40, this.largeLimestoneBricks);
		world.setBlock(i + 8, j + 2, k + 41, this.largeLimestoneBricks);
		world.setBlock(i + 8, j + 2, k + 42, this.largeLimestoneBricks);
		world.setBlock(i + 8, j + 3, k + 15, this.largeLimestoneBricks);
		world.setBlock(i + 8, j + 3, k + 38, this.largeLimestoneBricks);
		world.setBlock(i + 8, j + 3, k + 39, this.largeLimestoneBricks);
		world.setBlock(i + 8, j + 3, k + 40, this.largeLimestoneBricks);
		world.setBlock(i + 8, j + 3, k + 41, this.largeLimestoneBricks);
		world.setBlock(i + 8, j + 3, k + 42, this.largeLimestoneBricks);
		world.setBlock(i + 8, j + 4, k + 15, this.largeLimestoneBricks);
		world.setBlock(i + 8, j + 4, k + 39, this.largeLimestoneBricks);
		world.setBlock(i + 8, j + 4, k + 40, this.largeLimestoneBricks);
		world.setBlock(i + 8, j + 4, k + 41, this.largeLimestoneBricks);
		world.setBlock(i + 8, j + 4, k + 42, this.largeLimestoneBricks);
		world.setBlock(i + 8, j + 5, k + 15, this.largeLimestoneBricks);
		world.setBlock(i + 8, j + 5, k + 40, this.largeLimestoneBricks);
		world.setBlock(i + 8, j + 5, k + 41, this.largeLimestoneBricks);
		world.setBlock(i + 8, j + 5, k + 42, this.largeLimestoneBricks);
		world.setBlock(i + 8, j + 6, k + 9, this.largeLimestoneBricks);
		world.setBlock(i + 8, j + 6, k + 10, this.largeLimestoneBricks);
		world.setBlock(i + 8, j + 6, k + 11, this.largeLimestoneBricks);
		world.setBlock(i + 8, j + 6, k + 12, this.largeLimestoneBricks);
		world.setBlock(i + 8, j + 6, k + 13, this.largeLimestoneBricks);
		world.setBlock(i + 8, j + 6, k + 14, this.largeLimestoneBricks);
		world.setBlock(i + 8, j + 6, k + 15, this.largeLimestoneBricks);
		world.setBlock(i + 8, j + 6, k + 16, this.largeLimestoneBricks);
		world.setBlock(i + 8, j + 6, k + 17, this.largeLimestoneBricks);
		world.setBlock(i + 8, j + 6, k + 18, this.largeLimestoneBricks);
		world.setBlock(i + 8, j + 6, k + 19, this.largeLimestoneBricks);
		world.setBlock(i + 8, j + 6, k + 20, this.largeLimestoneBricks);
		world.setBlock(i + 8, j + 6, k + 21, this.largeLimestoneBricks);
		world.setBlock(i + 8, j + 6, k + 22, this.largeLimestoneBricks);
		world.setBlock(i + 8, j + 6, k + 23, this.largeLimestoneBricks);
		world.setBlock(i + 8, j + 6, k + 24, this.largeLimestoneBricks);
		world.setBlock(i + 8, j + 6, k + 25, this.largeLimestoneBricks);
		world.setBlock(i + 8, j + 6, k + 26, this.largeLimestoneBricks);
		world.setBlock(i + 8, j + 6, k + 27, this.largeLimestoneBricks);
		world.setBlock(i + 8, j + 6, k + 28, this.largeLimestoneBricks);
		world.setBlock(i + 8, j + 6, k + 29, this.largeLimestoneBricks);
		world.setBlock(i + 8, j + 6, k + 30, this.largeLimestoneBricks);
		world.setBlock(i + 8, j + 6, k + 31, this.largeLimestoneBricks);
		world.setBlock(i + 8, j + 6, k + 32, this.largeLimestoneBricks);
		world.setBlock(i + 8, j + 6, k + 33, this.largeLimestoneBricks);
		world.setBlock(i + 8, j + 6, k + 34, this.largeLimestoneBricks);
		world.setBlock(i + 8, j + 6, k + 35, this.largeLimestoneBricks);
		world.setBlock(i + 8, j + 6, k + 41, this.largeLimestoneBricks);
		world.setBlock(i + 8, j + 6, k + 42, this.largeLimestoneBricks);
		world.setBlock(i + 8, j + 6, k + 43, this.largeLimestoneBricks);
		world.setBlock(i + 8, j + 6, k + 44, this.largeLimestoneBricks);
		world.setBlock(i + 8, j + 6, k + 45, this.largeLimestoneBricks);
		world.setBlock(i + 8, j + 6, k + 46, this.largeLimestoneBricks);
		world.setBlock(i + 8, j + 6, k + 47, this.largeLimestoneBricks);
		world.setBlock(i + 8, j + 6, k + 48, this.largeLimestoneBricks);
		world.setBlock(i + 8, j + 7, k + 15, this.largeLimestoneBricks);
		world.setBlock(i + 8, j + 7, k + 16, Block.netherrack.blockID);
		world.setBlock(i + 8, j + 7, k + 17, this.largeLimestoneBricks);
		world.setBlock(i + 8, j + 7, k + 19, this.largeLimestoneBricks);
		world.setBlock(i + 8, j + 7, k + 20, this.largeLimestoneBricks);
		world.setBlock(i + 8, j + 7, k + 21, this.largeLimestoneBricks);
		world.setBlock(i + 8, j + 7, k + 23, this.largeLimestoneBricks);
		world.setBlock(i + 8, j + 7, k + 24, this.largeLimestoneBricks);
		world.setBlock(i + 8, j + 7, k + 25, this.largeLimestoneBricks);
		world.setBlock(i + 8, j + 7, k + 27, this.largeLimestoneBricks);
		world.setBlock(i + 8, j + 7, k + 28, this.largeLimestoneBricks);
		world.setBlock(i + 8, j + 7, k + 29, this.largeLimestoneBricks);
		world.setBlock(i + 8, j + 7, k + 31, this.largeLimestoneBricks);
		world.setBlock(i + 8, j + 7, k + 32, this.largeLimestoneBricks);
		world.setBlock(i + 8, j + 7, k + 33, this.largeLimestoneBricks);
		world.setBlock(i + 8, j + 7, k + 42, this.largeLimestoneBricks);
		world.setBlock(i + 8, j + 8, k + 15, this.largeLimestoneBricks);
		world.setBlock(i + 8, j + 8, k + 16, Block.fire.blockID);
		world.setBlock(i + 8, j + 8, k + 19, Block.bookShelf.blockID);
		world.setBlock(i + 8, j + 8, k + 20, Block.bookShelf.blockID);
		world.setBlock(i + 8, j + 8, k + 21, Block.bookShelf.blockID);
		world.setBlock(i + 8, j + 8, k + 23, Block.bookShelf.blockID);
		world.setBlock(i + 8, j + 8, k + 24, Block.bookShelf.blockID);
		world.setBlock(i + 8, j + 8, k + 25, Block.bookShelf.blockID);
		world.setBlock(i + 8, j + 8, k + 27, Block.bookShelf.blockID);
		world.setBlock(i + 8, j + 8, k + 28, Block.bookShelf.blockID);
		world.setBlock(i + 8, j + 8, k + 29, Block.bookShelf.blockID);
		world.setBlock(i + 8, j + 8, k + 31, Block.bookShelf.blockID);
		world.setBlock(i + 8, j + 8, k + 32, Block.bookShelf.blockID);
		world.setBlock(i + 8, j + 8, k + 33, Block.bookShelf.blockID);
		world.setBlock(i + 8, j + 8, k + 42, this.largeLimestoneBricks);
		world.setBlock(i + 8, j + 9, k + 15, this.largeLimestoneBricks);
		world.setBlock(i + 8, j + 9, k + 19, Block.bookShelf.blockID);
		world.setBlock(i + 8, j + 9, k + 20, Block.bookShelf.blockID);
		world.setBlock(i + 8, j + 9, k + 21, Block.bookShelf.blockID);
		world.setBlock(i + 8, j + 9, k + 23, Block.bookShelf.blockID);
		world.setBlock(i + 8, j + 9, k + 24, Block.bookShelf.blockID);
		world.setBlock(i + 8, j + 9, k + 25, Block.bookShelf.blockID);
		world.setBlock(i + 8, j + 9, k + 27, Block.bookShelf.blockID);
		world.setBlock(i + 8, j + 9, k + 28, Block.bookShelf.blockID);
		world.setBlock(i + 8, j + 9, k + 29, Block.bookShelf.blockID);
		world.setBlock(i + 8, j + 9, k + 31, Block.bookShelf.blockID);
		world.setBlock(i + 8, j + 9, k + 32, Block.bookShelf.blockID);
		world.setBlock(i + 8, j + 9, k + 33, Block.bookShelf.blockID);
		world.setBlock(i + 8, j + 9, k + 42, this.largeLimestoneBricks);
		world.setBlock(i + 8, j + 10, k + 15, this.largeLimestoneBricks);
		world.setBlock(i + 8, j + 10, k + 17, this.largeLimestoneBricks);
		world.setBlock(i + 8, j + 10, k + 19, this.largeLimestoneBricks);
		world.setBlock(i + 8, j + 10, k + 20, this.largeLimestoneBricks);
		world.setBlock(i + 8, j + 10, k + 21, this.largeLimestoneBricks);
		world.setBlock(i + 8, j + 10, k + 23, this.largeLimestoneBricks);
		world.setBlock(i + 8, j + 10, k + 24, this.largeLimestoneBricks);
		world.setBlock(i + 8, j + 10, k + 25, this.largeLimestoneBricks);
		world.setBlock(i + 8, j + 10, k + 27, this.largeLimestoneBricks);
		world.setBlock(i + 8, j + 10, k + 28, this.largeLimestoneBricks);
		world.setBlock(i + 8, j + 10, k + 29, this.largeLimestoneBricks);
		world.setBlock(i + 8, j + 10, k + 31, this.largeLimestoneBricks);
		world.setBlock(i + 8, j + 10, k + 32, this.largeLimestoneBricks);
		world.setBlock(i + 8, j + 10, k + 33, this.largeLimestoneBricks);
		world.setBlock(i + 8, j + 10, k + 42, this.largeLimestoneBricks);
		world.setBlock(i + 8, j + 11, k + 14, this.largeLimestoneBricks);
		world.setBlock(i + 8, j + 11, k + 15, this.largeLimestoneBricks);
		world.setBlock(i + 8, j + 11, k + 16, this.largeLimestoneBricks);
		world.setBlock(i + 8, j + 11, k + 17, this.largeLimestoneBricks);
		world.setBlock(i + 8, j + 11, k + 18, this.largeLimestoneBricks);
		world.setBlock(i + 8, j + 11, k + 19, this.largeLimestoneBricks);
		world.setBlock(i + 8, j + 11, k + 20, this.largeLimestoneBricks);
		world.setBlock(i + 8, j + 11, k + 21, this.largeLimestoneBricks);
		world.setBlock(i + 8, j + 11, k + 22, this.largeLimestoneBricks);
		world.setBlock(i + 8, j + 11, k + 23, this.largeLimestoneBricks);
		world.setBlock(i + 8, j + 11, k + 24, this.largeLimestoneBricks);
		world.setBlock(i + 8, j + 11, k + 25, this.largeLimestoneBricks);
		world.setBlock(i + 8, j + 11, k + 26, this.largeLimestoneBricks);
		world.setBlock(i + 8, j + 11, k + 27, this.largeLimestoneBricks);
		world.setBlock(i + 8, j + 11, k + 28, this.largeLimestoneBricks);
		world.setBlock(i + 8, j + 11, k + 29, this.largeLimestoneBricks);
		world.setBlock(i + 8, j + 11, k + 30, this.largeLimestoneBricks);
		world.setBlock(i + 8, j + 11, k + 31, this.largeLimestoneBricks);
		world.setBlock(i + 8, j + 11, k + 32, this.largeLimestoneBricks);
		world.setBlock(i + 8, j + 11, k + 33, this.largeLimestoneBricks);
		world.setBlock(i + 8, j + 11, k + 34, this.largeLimestoneBricks);
		world.setBlock(i + 8, j + 11, k + 35, this.largeLimestoneBricks);
		world.setBlock(i + 8, j + 11, k + 36, this.largeLimestoneBricks);
		world.setBlock(i + 8, j + 11, k + 37, this.largeLimestoneBricks);
		world.setBlock(i + 8, j + 11, k + 38, this.largeLimestoneBricks);
		world.setBlock(i + 8, j + 11, k + 39, this.largeLimestoneBricks);
		world.setBlock(i + 8, j + 11, k + 40, this.largeLimestoneBricks);
		world.setBlock(i + 8, j + 11, k + 41, this.largeLimestoneBricks);
		world.setBlock(i + 8, j + 11, k + 42, this.largeLimestoneBricks);
		world.setBlock(i + 8, j + 11, k + 43, this.largeLimestoneBricks);
		world.setBlock(i + 9, j + 0, k + 8, this.largeLimestoneBricks);
		world.setBlock(i + 9, j + 0, k + 49, this.largeLimestoneBricks);
		world.setBlock(i + 9, j + 1, k + 8, this.largeLimestoneBricks);
		world.setBlock(i + 9, j + 1, k + 9, this.largeLimestoneBricks);
		world.setBlock(i + 9, j + 1, k + 10, this.largeLimestoneBricks);
		world.setBlock(i + 9, j + 1, k + 11, this.largeLimestoneBricks);
		world.setBlock(i + 9, j + 1, k + 12, this.largeLimestoneBricks);
		world.setBlock(i + 9, j + 1, k + 13, this.largeLimestoneBricks);
		world.setBlock(i + 9, j + 1, k + 14, this.largeLimestoneBricks);
		world.setBlock(i + 9, j + 1, k + 15, this.largeLimestoneBricks);
		world.setBlock(i + 9, j + 1, k + 16, this.largeLimestoneBricks);
		world.setBlock(i + 9, j + 1, k + 17, this.largeLimestoneBricks);
		world.setBlock(i + 9, j + 1, k + 18, this.largeLimestoneBricks);
		world.setBlock(i + 9, j + 1, k + 19, this.largeLimestoneBricks);
		world.setBlock(i + 9, j + 1, k + 20, this.largeLimestoneBricks);
		world.setBlock(i + 9, j + 1, k + 21, this.largeLimestoneBricks);
		world.setBlock(i + 9, j + 1, k + 22, this.largeLimestoneBricks);
		world.setBlock(i + 9, j + 1, k + 23, this.largeLimestoneBricks);
		world.setBlock(i + 9, j + 1, k + 24, this.largeLimestoneBricks);
		world.setBlock(i + 9, j + 1, k + 25, this.largeLimestoneBricks);
		world.setBlock(i + 9, j + 1, k + 26, this.largeLimestoneBricks);
		world.setBlock(i + 9, j + 1, k + 27, this.largeLimestoneBricks);
		world.setBlock(i + 9, j + 1, k + 28, this.largeLimestoneBricks);
		world.setBlock(i + 9, j + 1, k + 29, this.largeLimestoneBricks);
		world.setBlock(i + 9, j + 1, k + 30, this.largeLimestoneBricks);
		world.setBlock(i + 9, j + 1, k + 31, this.largeLimestoneBricks);
		world.setBlock(i + 9, j + 1, k + 32, this.largeLimestoneBricks);
		world.setBlock(i + 9, j + 1, k + 33, this.largeLimestoneBricks);
		world.setBlock(i + 9, j + 1, k + 34, this.largeLimestoneBricks);
		world.setBlock(i + 9, j + 1, k + 35, this.largeLimestoneBricks);
		world.setBlock(i + 9, j + 1, k + 36, this.largeLimestoneBricks);
		world.setBlock(i + 9, j + 1, k + 37, this.largeLimestoneBricks);
		world.setBlock(i + 9, j + 1, k + 38, this.largeLimestoneBricks);
		world.setBlock(i + 9, j + 1, k + 39, this.largeLimestoneBricks);
		world.setBlock(i + 9, j + 1, k + 40, this.largeLimestoneBricks);
		world.setBlock(i + 9, j + 1, k + 41, this.largeLimestoneBricks);
		world.setBlock(i + 9, j + 1, k + 42, this.largeLimestoneBricks);
		world.setBlock(i + 9, j + 1, k + 43, this.largeLimestoneBricks);
		world.setBlock(i + 9, j + 1, k + 44, this.largeLimestoneBricks);
		world.setBlock(i + 9, j + 1, k + 45, this.largeLimestoneBricks);
		world.setBlock(i + 9, j + 1, k + 46, this.largeLimestoneBricks);
		world.setBlock(i + 9, j + 1, k + 47, this.largeLimestoneBricks);
		world.setBlock(i + 9, j + 1, k + 48, this.largeLimestoneBricks);
		world.setBlock(i + 9, j + 1, k + 49, this.largeLimestoneBricks);
		world.setBlock(i + 9, j + 2, k + 15, this.largeLimestoneBricks);
		world.setBlock(i + 9, j + 2, k + 37, this.largeLimestoneBricks);
		world.setBlock(i + 9, j + 2, k + 38, this.largeLimestoneBricks);
		world.setBlock(i + 9, j + 2, k + 39, this.largeLimestoneBricks);
		world.setBlock(i + 9, j + 2, k + 40, this.largeLimestoneBricks);
		world.setBlock(i + 9, j + 2, k + 41, this.largeLimestoneBricks);
		world.setBlock(i + 9, j + 2, k + 42, this.largeLimestoneBricks);
		world.setBlock(i + 9, j + 3, k + 15, this.largeLimestoneBricks);
		world.setBlock(i + 9, j + 3, k + 38, this.largeLimestoneBricks);
		world.setBlock(i + 9, j + 3, k + 39, this.largeLimestoneBricks);
		world.setBlock(i + 9, j + 3, k + 40, this.largeLimestoneBricks);
		world.setBlock(i + 9, j + 3, k + 41, this.largeLimestoneBricks);
		world.setBlock(i + 9, j + 3, k + 42, this.largeLimestoneBricks);
		world.setBlock(i + 9, j + 4, k + 15, this.largeLimestoneBricks);
		world.setBlock(i + 9, j + 4, k + 39, this.largeLimestoneBricks);
		world.setBlock(i + 9, j + 4, k + 40, this.largeLimestoneBricks);
		world.setBlock(i + 9, j + 4, k + 41, this.largeLimestoneBricks);
		world.setBlock(i + 9, j + 4, k + 42, this.largeLimestoneBricks);
		world.setBlock(i + 9, j + 5, k + 15, this.largeLimestoneBricks);
		world.setBlock(i + 9, j + 5, k + 40, this.largeLimestoneBricks);
		world.setBlock(i + 9, j + 5, k + 41, this.largeLimestoneBricks);
		world.setBlock(i + 9, j + 5, k + 42, this.largeLimestoneBricks);
		world.setBlock(i + 9, j + 6, k + 9, this.largeLimestoneBricks);
		world.setBlock(i + 9, j + 6, k + 10, this.largeLimestoneBricks);
		world.setBlock(i + 9, j + 6, k + 11, this.largeLimestoneBricks);
		world.setBlock(i + 9, j + 6, k + 12, this.largeLimestoneBricks);
		world.setBlock(i + 9, j + 6, k + 13, this.largeLimestoneBricks);
		world.setBlock(i + 9, j + 6, k + 14, this.largeLimestoneBricks);
		world.setBlock(i + 9, j + 6, k + 15, this.largeLimestoneBricks);
		world.setBlock(i + 9, j + 6, k + 16, this.largeLimestoneBricks);
		world.setBlock(i + 9, j + 6, k + 17, this.largeLimestoneBricks);
		world.setBlock(i + 9, j + 6, k + 18, this.largeLimestoneBricks);
		world.setBlock(i + 9, j + 6, k + 19, this.largeLimestoneBricks);
		world.setBlock(i + 9, j + 6, k + 20, this.largeLimestoneBricks);
		world.setBlock(i + 9, j + 6, k + 21, this.largeLimestoneBricks);
		world.setBlock(i + 9, j + 6, k + 22, this.largeLimestoneBricks);
		world.setBlock(i + 9, j + 6, k + 23, this.largeLimestoneBricks);
		world.setBlock(i + 9, j + 6, k + 24, this.largeLimestoneBricks);
		world.setBlock(i + 9, j + 6, k + 25, this.largeLimestoneBricks);
		world.setBlock(i + 9, j + 6, k + 26, this.largeLimestoneBricks);
		world.setBlock(i + 9, j + 6, k + 27, this.largeLimestoneBricks);
		world.setBlock(i + 9, j + 6, k + 28, this.largeLimestoneBricks);
		world.setBlock(i + 9, j + 6, k + 29, this.largeLimestoneBricks);
		world.setBlock(i + 9, j + 6, k + 30, this.largeLimestoneBricks);
		world.setBlock(i + 9, j + 6, k + 31, this.largeLimestoneBricks);
		world.setBlock(i + 9, j + 6, k + 32, this.largeLimestoneBricks);
		world.setBlock(i + 9, j + 6, k + 33, this.largeLimestoneBricks);
		world.setBlock(i + 9, j + 6, k + 34, this.largeLimestoneBricks);
		world.setBlock(i + 9, j + 6, k + 35, this.largeLimestoneBricks);
		world.setBlock(i + 9, j + 6, k + 41, this.largeLimestoneBricks);
		world.setBlock(i + 9, j + 6, k + 42, this.largeLimestoneBricks);
		world.setBlock(i + 9, j + 6, k + 43, this.largeLimestoneBricks);
		world.setBlock(i + 9, j + 6, k + 44, this.largeLimestoneBricks);
		world.setBlock(i + 9, j + 6, k + 45, this.largeLimestoneBricks);
		world.setBlock(i + 9, j + 6, k + 46, this.largeLimestoneBricks);
		world.setBlock(i + 9, j + 6, k + 47, this.largeLimestoneBricks);
		world.setBlock(i + 9, j + 6, k + 48, this.largeLimestoneBricks);
		world.setBlock(i + 9, j + 7, k + 15, this.largeLimestoneBricks);
		world.setBlock(i + 9, j + 7, k + 16, this.largeLimestoneBricks);
		world.setBlock(i + 9, j + 7, k + 17, this.largeLimestoneBricks);
		world.setBlock(i + 9, j + 7, k + 42, this.largeLimestoneBricks);
		world.setBlock(i + 9, j + 8, k + 15, this.largeLimestoneBricks);
		world.setBlock(i + 9, j + 8, k + 42, this.largeLimestoneBricks);
		world.setBlock(i + 9, j + 9, k + 15, this.largeLimestoneBricks);
		world.setBlock(i + 9, j + 9, k + 42, this.largeLimestoneBricks);
		world.setBlock(i + 9, j + 10, k + 15, this.largeLimestoneBricks);
		world.setBlock(i + 9, j + 10, k + 16, this.largeLimestoneBricks);
		world.setBlock(i + 9, j + 10, k + 17, this.largeLimestoneBricks);
		world.setBlock(i + 9, j + 10, k + 42, this.largeLimestoneBricks);
		world.setBlock(i + 9, j + 11, k + 14, this.largeLimestoneBricks);
		world.setBlock(i + 9, j + 11, k + 15, this.largeLimestoneBricks);
		world.setBlock(i + 9, j + 11, k + 16, this.largeLimestoneBricks);
		world.setBlock(i + 9, j + 11, k + 17, this.largeLimestoneBricks);
		world.setBlock(i + 9, j + 11, k + 18, this.largeLimestoneBricks);
		world.setBlock(i + 9, j + 11, k + 19, this.largeLimestoneBricks);
		world.setBlock(i + 9, j + 11, k + 20, this.largeLimestoneBricks);
		world.setBlock(i + 9, j + 11, k + 21, this.largeLimestoneBricks);
		world.setBlock(i + 9, j + 11, k + 22, this.largeLimestoneBricks);
		world.setBlock(i + 9, j + 11, k + 23, this.largeLimestoneBricks);
		world.setBlock(i + 9, j + 11, k + 24, this.largeLimestoneBricks);
		world.setBlock(i + 9, j + 11, k + 25, this.largeLimestoneBricks);
		world.setBlock(i + 9, j + 11, k + 26, this.largeLimestoneBricks);
		world.setBlock(i + 9, j + 11, k + 27, this.largeLimestoneBricks);
		world.setBlock(i + 9, j + 11, k + 28, this.largeLimestoneBricks);
		world.setBlock(i + 9, j + 11, k + 29, this.largeLimestoneBricks);
		world.setBlock(i + 9, j + 11, k + 30, this.largeLimestoneBricks);
		world.setBlock(i + 9, j + 11, k + 31, this.largeLimestoneBricks);
		world.setBlock(i + 9, j + 11, k + 32, this.largeLimestoneBricks);
		world.setBlock(i + 9, j + 11, k + 33, this.largeLimestoneBricks);
		world.setBlock(i + 9, j + 11, k + 34, this.largeLimestoneBricks);
		world.setBlock(i + 9, j + 11, k + 35, this.largeLimestoneBricks);
		world.setBlock(i + 9, j + 11, k + 36, this.largeLimestoneBricks);
		world.setBlock(i + 9, j + 11, k + 37, this.largeLimestoneBricks);
		world.setBlock(i + 9, j + 11, k + 38, this.largeLimestoneBricks);
		world.setBlock(i + 9, j + 11, k + 39, this.largeLimestoneBricks);
		world.setBlock(i + 9, j + 11, k + 40, this.largeLimestoneBricks);
		world.setBlock(i + 9, j + 11, k + 41, this.largeLimestoneBricks);
		world.setBlock(i + 9, j + 11, k + 42, this.largeLimestoneBricks);
		world.setBlock(i + 9, j + 11, k + 43, this.largeLimestoneBricks);
		world.setBlock(i + 10, j + 0, k + 8, this.largeLimestoneBricks);
		world.setBlock(i + 10, j + 0, k + 49, this.largeLimestoneBricks);
		world.setBlock(i + 10, j + 1, k + 8, this.largeLimestoneBricks);
		world.setBlock(i + 10, j + 1, k + 9, this.largeLimestoneBricks);
		world.setBlock(i + 10, j + 1, k + 10, this.largeLimestoneBricks);
		world.setBlock(i + 10, j + 1, k + 11, this.largeLimestoneBricks);
		world.setBlock(i + 10, j + 1, k + 12, this.largeLimestoneBricks);
		world.setBlock(i + 10, j + 1, k + 13, this.largeLimestoneBricks);
		world.setBlock(i + 10, j + 1, k + 14, this.largeLimestoneBricks);
		world.setBlock(i + 10, j + 1, k + 15, this.largeLimestoneBricks);
		world.setBlock(i + 10, j + 1, k + 16, this.largeLimestoneBricks);
		world.setBlock(i + 10, j + 1, k + 17, this.largeLimestoneBricks);
		world.setBlock(i + 10, j + 1, k + 18, this.largeLimestoneBricks);
		world.setBlock(i + 10, j + 1, k + 19, this.largeLimestoneBricks);
		world.setBlock(i + 10, j + 1, k + 20, this.largeLimestoneBricks);
		world.setBlock(i + 10, j + 1, k + 21, this.largeLimestoneBricks);
		world.setBlock(i + 10, j + 1, k + 22, this.largeLimestoneBricks);
		world.setBlock(i + 10, j + 1, k + 23, this.largeLimestoneBricks);
		world.setBlock(i + 10, j + 1, k + 24, this.largeLimestoneBricks);
		world.setBlock(i + 10, j + 1, k + 25, this.largeLimestoneBricks);
		world.setBlock(i + 10, j + 1, k + 26, this.largeLimestoneBricks);
		world.setBlock(i + 10, j + 1, k + 27, this.largeLimestoneBricks);
		world.setBlock(i + 10, j + 1, k + 28, this.largeLimestoneBricks);
		world.setBlock(i + 10, j + 1, k + 29, this.largeLimestoneBricks);
		world.setBlock(i + 10, j + 1, k + 30, this.largeLimestoneBricks);
		world.setBlock(i + 10, j + 1, k + 31, this.largeLimestoneBricks);
		world.setBlock(i + 10, j + 1, k + 32, this.largeLimestoneBricks);
		world.setBlock(i + 10, j + 1, k + 33, this.largeLimestoneBricks);
		world.setBlock(i + 10, j + 1, k + 34, this.largeLimestoneBricks);
		world.setBlock(i + 10, j + 1, k + 35, this.largeLimestoneBricks);
		world.setBlock(i + 10, j + 1, k + 36, this.largeLimestoneBricks);
		world.setBlock(i + 10, j + 1, k + 37, this.largeLimestoneBricks);
		world.setBlock(i + 10, j + 1, k + 38, this.largeLimestoneBricks);
		world.setBlock(i + 10, j + 1, k + 39, this.largeLimestoneBricks);
		world.setBlock(i + 10, j + 1, k + 40, this.largeLimestoneBricks);
		world.setBlock(i + 10, j + 1, k + 41, this.largeLimestoneBricks);
		world.setBlock(i + 10, j + 1, k + 42, this.largeLimestoneBricks);
		world.setBlock(i + 10, j + 1, k + 43, this.largeLimestoneBricks);
		world.setBlock(i + 10, j + 1, k + 44, this.largeLimestoneBricks);
		world.setBlock(i + 10, j + 1, k + 45, this.largeLimestoneBricks);
		world.setBlock(i + 10, j + 1, k + 46, this.largeLimestoneBricks);
		world.setBlock(i + 10, j + 1, k + 47, this.largeLimestoneBricks);
		world.setBlock(i + 10, j + 1, k + 48, this.largeLimestoneBricks);
		world.setBlock(i + 10, j + 1, k + 49, this.largeLimestoneBricks);
		world.setBlock(i + 10, j + 2, k + 9, this.largeLimestoneBricks);
		world.setBlock(i + 10, j + 2, k + 14, this.largeLimestoneBricks);
		world.setBlock(i + 10, j + 2, k + 15, this.largeLimestoneBricks);
		world.setBlock(i + 10, j + 2, k + 22, this.largeLimestoneBricks);
		world.setBlock(i + 10, j + 2, k + 23, this.largeLimestoneBricks);
		world.setBlock(i + 10, j + 2, k + 24, this.largeLimestoneBricks);
		world.setBlock(i + 10, j + 2, k + 25, this.largeLimestoneBricks);
		world.setBlock(i + 10, j + 2, k + 26, this.largeLimestoneBricks);
		world.setBlock(i + 10, j + 2, k + 30, this.largeLimestoneBricks);
		world.setBlock(i + 10, j + 2, k + 31, this.largeLimestoneBricks);
		world.setBlock(i + 10, j + 2, k + 32, this.largeLimestoneBricks);
		world.setBlock(i + 10, j + 2, k + 33, this.largeLimestoneBricks);
		world.setBlock(i + 10, j + 2, k + 34, this.largeLimestoneBricks);
		world.setBlock(i + 10, j + 2, k + 42, this.largeLimestoneBricks);
		world.setBlock(i + 10, j + 2, k + 43, this.largeLimestoneBricks);
		world.setBlock(i + 10, j + 2, k + 48, this.largeLimestoneBricks);
		world.setBlock(i + 10, j + 3, k + 15, this.largeLimestoneBricks);
		world.setBlock(i + 10, j + 3, k + 22, Block.bookShelf.blockID);
		world.setBlock(i + 10, j + 3, k + 23, Block.bookShelf.blockID);
		world.setBlock(i + 10, j + 3, k + 24, Block.bookShelf.blockID);
		world.setBlock(i + 10, j + 3, k + 25, Block.bookShelf.blockID);
		world.setBlock(i + 10, j + 3, k + 26, Block.bookShelf.blockID);
		world.setBlock(i + 10, j + 3, k + 30, Block.bookShelf.blockID);
		world.setBlock(i + 10, j + 3, k + 31, Block.bookShelf.blockID);
		world.setBlock(i + 10, j + 3, k + 32, Block.bookShelf.blockID);
		world.setBlock(i + 10, j + 3, k + 33, Block.bookShelf.blockID);
		world.setBlock(i + 10, j + 3, k + 34, Block.bookShelf.blockID);
		world.setBlock(i + 10, j + 3, k + 42, this.largeLimestoneBricks);
		world.setBlock(i + 10, j + 4, k + 15, this.largeLimestoneBricks);
		world.setBlock(i + 10, j + 4, k + 22, Block.bookShelf.blockID);
		world.setBlock(i + 10, j + 4, k + 23, Block.bookShelf.blockID);
		world.setBlock(i + 10, j + 4, k + 24, Block.bookShelf.blockID);
		world.setBlock(i + 10, j + 4, k + 25, Block.bookShelf.blockID);
		world.setBlock(i + 10, j + 4, k + 26, Block.bookShelf.blockID);
		world.setBlock(i + 10, j + 4, k + 30, Block.bookShelf.blockID);
		world.setBlock(i + 10, j + 4, k + 31, Block.bookShelf.blockID);
		world.setBlock(i + 10, j + 4, k + 32, Block.bookShelf.blockID);
		world.setBlock(i + 10, j + 4, k + 33, Block.bookShelf.blockID);
		world.setBlock(i + 10, j + 4, k + 34, Block.bookShelf.blockID);
		world.setBlock(i + 10, j + 4, k + 42, this.largeLimestoneBricks);
		world.setBlock(i + 10, j + 5, k + 9, this.largeLimestoneBricks);
		world.setBlock(i + 10, j + 5, k + 14, this.largeLimestoneBricks);
		world.setBlock(i + 10, j + 5, k + 15, this.largeLimestoneBricks);
		world.setBlock(i + 10, j + 5, k + 22, this.largeLimestoneBricks);
		world.setBlock(i + 10, j + 5, k + 23, this.largeLimestoneBricks);
		world.setBlock(i + 10, j + 5, k + 24, this.largeLimestoneBricks);
		world.setBlock(i + 10, j + 5, k + 25, this.largeLimestoneBricks);
		world.setBlock(i + 10, j + 5, k + 26, this.largeLimestoneBricks);
		world.setBlock(i + 10, j + 5, k + 30, this.largeLimestoneBricks);
		world.setBlock(i + 10, j + 5, k + 31, this.largeLimestoneBricks);
		world.setBlock(i + 10, j + 5, k + 32, this.largeLimestoneBricks);
		world.setBlock(i + 10, j + 5, k + 33, this.largeLimestoneBricks);
		world.setBlock(i + 10, j + 5, k + 34, this.largeLimestoneBricks);
		world.setBlock(i + 10, j + 5, k + 42, this.largeLimestoneBricks);
		world.setBlock(i + 10, j + 5, k + 43, this.largeLimestoneBricks);
		world.setBlock(i + 10, j + 5, k + 48, this.largeLimestoneBricks);
		world.setBlock(i + 10, j + 6, k + 9, this.largeLimestoneBricks);
		world.setBlock(i + 10, j + 6, k + 10, this.largeLimestoneBricks);
		world.setBlock(i + 10, j + 6, k + 11, this.largeLimestoneBricks);
